Workbook

Sheet README
A1: AI Infrastructure Stock Scoring System
A3: PURPOSE
A4: Rank AI supply chain stocks on a 0-100 scale to prioritize which names deserve a deep-dive.
A5: The score is NOT a buy/sell signal. It's a triage tool.
A7: HOW IT WORKS
A8: 6 categories, each scored 0-100, then weighted into a single total.
A9: Each category has 3-5 sub-metrics with thresholds defined on the Methodology sheet.
A11: CATEGORIES & DEFAULT WEIGHTS
A12: Value (20%) - Is the price reasonable vs. fundamentals?
A13: Quality (20%) - Is the business well-run and financially sound?
A14: Growth (15%) - Is the company growing meaningfully?
A15: AI Thesis (20%) - How strong is the AI infrastructure exposure?
... A51: Quarterly: re-run the scores, and grade yourself on whether last quarter's picks worked.

Sheet Weights
A1: Category Weights
A3: Category | B3: Weight (%) | C3: Notes
A4: Value | B4: 0.2 | C4: Is the price reasonable?
A5: Quality | B5: 0.2 | C5: Is the business well-run?
A6: Growth | B6: 0.15 | C6: Is it growing?
A7: AI Thesis | B7: 0.2 | C7: How strong is AI exposure?
A8: Momentum | B8: 0.1 | C8: Are estimates and price improving?
A9: Risk | B9: 0.15 | C9: Concentration / geographic / regulatory
A10: TOTAL | B10: =SUM(B4:B9)
A12: ⚠️ Weights must sum to 100%. Adjust the yellow cells above.

Sheet Methodology
A1: Scoring Methodology - Threshold Bands
A3: Each metric is converted to a 0-100 score using the bands below.
A4: Subscores are computed as the average of the metrics within each category.
A5: Edit the threshold cells (blue) if you want to tighten or loosen any standard.
A7: VALUE | J7: Negative-value note
A8: └ Layer 10 carve-out (rule 10, 2026-05-26): col F holds EV/FCF (statement TTM FCF) | B8: Threshold: | C8: ≤20 → 100 | D8: ≤30 → 90 | E8: ≤40 → 75 | F8: ≤55 → 60 | G8: ≤75 → 45 | H8: ≤100 → 30 | I8: >100 → 15 | J8: Negative FCF → 5. Bands were documented in CLAUDE.md 2026-05-26 but only implemented in formulas 2026-06-12 (rebuild_watchlist_formulas.py).
A9: └ Layer 9 capacity carve-out (rule 13, 2026-06-12): col F holds EV / secured gross MW ($M/MW) | B9: Threshold: | C9: ≤2 → 100 | D9: ≤4 → 90 | E9: ≤6 → 75 | F9: ≤9 → 60 | G9: ≤12 → 45 | H9: ≤18 → 30 | I9: >18 → 15 | J9: Cohort: Layer 9 bitcoin-miner pivots + neoclouds (hyperscalers excluded). MW data + provenance: 00-master/capacity-mw.json. Anchor: ~$9-10M/gross-MW AI DC replacement cost at the 45/60 boundary. IT-load-only disclosures converted ×1.25 (flagged in json).
A10: Forward P/E (lower = better) | B10: Threshold: | C10: ≥0 → 100 | D10: ≥15 → 90 | E10: ≥20 → 75 | F10: ≥25 → 60 | G10: ≥30 → 45 | H10: ≥40 → 30 | I10: ≥60 → 15 | J10: If Fwd P/E < 0 (forward EPS estimate negative — losing money), returns 5 (worst band). Patched 2026-05-18.
A11: EV/EBITDA (lower = better) | B11: Threshold: | C11: ≥0 → 100 | D11: ≥10 → 90 | E11: ≥15 → 75 | F11: ≥20 → 60 | G11: ≥25 → 45 | H11: ≥35 → 30 | I11: ≥50 → 15 | J11: If EV/EBITDA < 0 (negative EBITDA — operations unprofitable), returns 5 (worst band). Patched 2026-05-18.
A12: FCF Yield % (higher = better) | B12: Threshold: | C12: ≥8 → 100 | D12: ≥6 → 90 | E12: ≥4 → 75 | F12: ≥2 → 60 | G12: ≥1 → 45 | H12: ≥0 → 30 | I12: ≥-2 → 15
A13: Price / Sales (lower = better) | I13: ≥25 → 15
A14: PEG Ratio (lower = better) | B14: Threshold: | C14: ≤0.5 → 100 | D14: ≤1.0 → 90 | E14: ≤1.5 → 75 | F14: ≤2.0 → 60 | G14: ≤2.5 → 45 | H14: ≤3.0 → 30 | I14: >3.0 → 15 | J14: PEG = Fwd P/E ÷ EPS Growth %. Undefined when EPS growth ≤ 0 (excluded from avg).
A16: QUALITY
A17: ROIC % (higher = better) | B17: Threshold: | C17: ≥25 → 100 | D17: ≥20 → 90 | E17: ≥15 → 75 | F17: ≥10 → 60 | G17: ≥5 → 45 | H17: ≥0 → 30 | I17: ≥-5 → 15
A18: Gross Margin % (higher = better) | B18: Threshold: | C18: ≥60 → 100 | D18: ≥50 → 90 | E18: ≥40 → 75 | F18: ≥30 → 60 | G18: ≥20 → 45 | H18: ≥10 → 30 | I18: ≥0 → 15
A19: FCF Margin % (higher = better) | I19: ≥-10 → 15
A20: Net Debt / EBITDA (lower = better) | B20: Threshold: | C20: ≥0 → 100 | D20: ≥1 → 90 | E20: ≥2 → 75 | F20: ≥3 → 60 | G20: ≥4 → 45 | H20: ≥5 → 30 | I20: ≥7 → 15 | J20: ND/EBITDA can be negative two ways: (a) net cash with positive EBITDA = 100 (correct); (b) negative EBITDA = treated as 100 (WRONG — see batch_score.py guard that excludes when EBITDA<0).
A22: GROWTH
A23: Revenue 3yr CAGR % (higher = better) | B23: Threshold: | C23: ≥40 → 100 | D23: ≥30 → 90 | E23: ≥20 → 75 | F23: ≥15 → 60 | G23: ≥10 → 45 | H23: ≥5 → 30 | I23: ≥0 → 15
A24: Revenue YoY % most recent qtr | I24: ≥-10 → 15
A25: EPS Growth YoY % | B25: Threshold: | C25: ≥40 → 100 | D25: ≥30 → 90 | E25: ≥20 → 75 | F25: ≥10 → 60 | G25: ≥0 → 45 | H25: ≥-10 → 30 | I25: ≥-25 → 15 | J25: Rule 15 (2026-06-12): blank this input when the YoY change is dominated by disclosed non-operating one-time items (divestiture gains, FV swings) — applied on documented evidence per name, not mechanically on magnitude. First application: GEV (Prolec gain).
A27: AI THESIS (subjective 1-5, score = rating × 20)
A28: AI Revenue % of total (1=<5%, 5=>50%)
A29: Supply Chain Position (1=downstream/commodity, 5=upstream/bottleneck)
A30: Moat Strength (1=none, 5=durable)
A31: Capacity Expansion (1=shrinking, 5=major buildout)
A32: Hyperscaler Exposure (1=none, 5=multiple anchor customers)
A34: MOMENTUM (subjective 1-5 except 50DMA %, which is objective and banded)
A35: EPS Revisions last 90d (1=cuts, 5=raises)
A36: Relative Strength vs Sector (1=lagging, 5=leading)
A37: Insider Activity (1=heavy selling, 3=neutral, 5=buying)
A38: % days above 50-DMA, last 120 trading days (higher = better) | B38: Threshold: | C38: ≥85 → 100 | D38: ≥70 → 90 | E38: ≥55 → 75 | F38: ≥40 → 60 | G38: ≥25 → 40 | H38: <25 → 20 | J38: Added 2026-06-09. Share of last 120 trading days with close > 50-day SMA, from yfinance price history (scripts/momentum_50dma.py). Separates consistent uptrends from one-bounce moves. Names with <60 days of valid history are left blank and flagged.
A40: RISK (subjective 1-5; 5 = LOW risk)
A41: Customer Concentration (1=top customer>50%, 5=diversified)
A42: Geographic/Export Risk (1=high China/export, 5=domestic safe)
A43: Balance Sheet Risk (1=stressed, 5=fortress)
A44: Regulatory/Litigation Risk (1=major overhang, 5=clean)
A45: Disruption Risk / business-model durability (1=AI directly produces output+active erosion, 5=no credible disruption; DEFAULT 5 non-Layer-10) [added 2026-06-17, rule 16]
A47: P1 COHORT-RELATIVE SCORING (2026-07-02, rule 20): EV/EBITDA, FCF-Yield, P/S, ROIC, Gross Margin and FCF Margin are percentile-ranked WITHIN each top-level-layer cohort (min 8 non-null, else the absolute band above is the fallback). Live via recalc_watchlist.recalc(mode=percentile); Value Score (J) and Quality Score (O) are recalc-maintained values. See CLAUDE.md rule 20.

Sheet Watchlist
A1: Ticker | B1: Company | C1: Layer | D1: Last Updated | E1: Fwd P/E | F1: EV/EBITDA | G1: FCF Yield % | H1: P/S | I1: PEG | J1: Value Score | K1: ROIC % | L1: Gross Mgn % | M1: FCF Mgn % | N1: ND/EBITDA | O1: Quality Score | P1: Rev 3y CAGR % | Q1: Rev YoY % | R1: EPS YoY % | S1: Growth Score | T1: AI Rev % | U1: Position | V1: Moat | W1: Capacity | X1: Hypersc. | Y1: AI Score | Z1: EPS Rev | AA1: Rel Str | AB1: Insider | AC1: 50DMA % | AD1: Momentum Score | AE1: Cust Conc | AF1: Geo Risk | AG1: BS Risk | AH1: Reg Risk | AI1: Risk Score | AJ1: TOTAL | AK1: Tier | AL1: Disrupt Risk
A2: BE | B2: Bloom Energy | C2: 01 Power - Distributed | D2: 2026-10-11 | E2: 56.757248 | F2: 205.314 | G2: 0.76 | H2: 26.537407 | I2: =IF(OR(E2="",R2="",R2<=0,E2<0),"",E2/R2) | J2: 30.9 | K2: 7.67 | L2: 31.65 | M2: 20.07 | N2: 0.23 | O2: 67.1 | P2: 19.06 | Q2: 165.5 | R2: 60 | S2: =IFERROR(AVERAGE(IFERROR(IF(P2="","",IF(P2>=40,100,IF(P2>=30,90,IF(P2>=20,75,IF(P2>=15,60,IF(P2>=10,45,IF(P2>=5,30,15))))))),""),IFERROR(IF(Q2="","",IF(Q2>=40,100,IF(Q2>=30,90,IF(Q2>=20,75,IF(Q2>=10,60,IF(Q2>=5,45,IF(Q2>=0,30,15))))))),""),IFERROR(IF(R2="","",IF(R2>=40,100,IF(R2>=30,90,IF(R2>=20,75,IF(R2>=10,60,IF(R2>=0,45,IF(R2>=-10,30,15))))))),"")),"") | T2: 5 | U2: 4 | V2: 4 | W2: 5 | X2: 4 | Y2: =IFERROR((AVERAGE(T2,U2,V2,W2,X2)-1)*25,"") | Z2: 5 | AA2: 5 | AB2: 3 | AC2: 62.5 | AD2: =IFERROR(AVERAGE(IFERROR(IF(Z2="","",Z2*20),""),IFERROR(IF(AA2="","",AA2*20),""),IFERROR(IF(AB2="","",AB2*20),""),IFERROR(IF(AC2="","",IF(AC2>=85,100,IF(AC2>=70,90,IF(AC2>=55,75,IF(AC2>=40,60,IF(AC2>=25,40,20)))))),"")),"") | AE2: 3 | AF2: 4 | AG2: 3 | AH2: 4 | AI2: =IFERROR((AVERAGE(AE2,AF2,AG2,AH2,AL2)-1)*25,"") | AJ2: =IFERROR(J2*Weights!$B$4 + O2*Weights!$B$5 + S2*Weights!$B$6 + Y2*Weights!$B$7 + AD2*Weights!$B$8 + AI2*Weights!$B$9,"") | AK2: =IF(AJ2="","",IF(AJ2>=85,"✓✓✓",IF(AJ2>=70,"✓✓",IF(AJ2>=55,"✓",IF(AJ2>=40,"?","✗"))))) | AL2: 5
A3: CRWV | B3: CoreWeave | C3: 09 Cloud - Neocloud | D3: 2026-10-11 | E3: -45.28402 | F3: 22.6 | G3: -30.16 | H3: 5.9644427 | I3: =IF(OR(E3="",R3="",R3<=0,E3<0),"",E3/R3) | J3: 27.5 | K3: -0.32 | L3: 67.42 | M3: -179.91 | N3: 12.16 | O3: 54.4 | P3: 586.92 | Q3: 112.5 | R3: 80 | S3: =IFERROR(AVERAGE(IFERROR(IF(P3="","",IF(P3>=40,100,IF(P3>=30,90,IF(P3>=20,75,IF(P3>=15,60,IF(P3>=10,45,IF(P3>=5,30,15))))))),""),IFERROR(IF(Q3="","",IF(Q3>=40,100,IF(Q3>=30,90,IF(Q3>=20,75,IF(Q3>=10,60,IF(Q3>=5,45,IF(Q3>=0,30,15))))))),""),IFERROR(IF(R3="","",IF(R3>=40,100,IF(R3>=30,90,IF(R3>=20,75,IF(R3>=10,60,IF(R3>=0,45,IF(R3>=-10,30,15))))))),"")),"") | T3: 5 | U3: 4 | V3: 3 | W3: 5 | X3: 5 | Y3: =IFERROR((AVERAGE(T3,U3,V3,W3,X3)-1)*25,"") | Z3: 5 | AA3: 5 | AB3: 2 | AC3: 46.7 | AD3: =IFERROR(AVERAGE(IFERROR(IF(Z3="","",Z3*20),""),IFERROR(IF(AA3="","",AA3*20),""),IFERROR(IF(AB3="","",AB3*20),""),IFERROR(IF(AC3="","",IF(AC3>=85,100,IF(AC3>=70,90,IF(AC3>=55,75,IF(AC3>=40,60,IF(AC3>=25,40,20)))))),"")),"") | AE3: 2 | AF3: 5 | AG3: 1 | AH3: 4 | AI3: =IFERROR((AVERAGE(AE3,AF3,AG3,AH3,AL3)-1)*25,"") | AJ3: =IFERROR(J3*Weights!$B$4 + O3*Weights!$B$5 + S3*Weights!$B$6 + Y3*Weights!$B$7 + AD3*Weights!$B$8 + AI3*Weights!$B$9,"") | AK3: =IF(AJ3="","",IF(AJ3>=85,"✓✓✓",IF(AJ3>=70,"✓✓",IF(AJ3>=55,"✓",IF(AJ3>=40,"?","✗"))))) | AL3: 5
A4: VRT | B4: Vertiv Holdings | C4: 03 DC Infrastructure | D4: 2026-10-11 | E4: 26.450916 | F4: 35.51 | G4: 3.13 | H4: 8.142046 | I4: =IF(OR(E4="",R4="",R4<=0,E4<0),"",E4/R4) | J4: 51.7 | K4: 21.07 | L4: 38.04 | M4: 25.47 | N4: 0.08 | O4: 80.5 | P4: 21.59 | Q4: 24.1 | R4: 53.5 | S4: =IFERROR(AVERAGE(IFERROR(IF(P4="","",IF(P4>=40,100,IF(P4>=30,90,IF(P4>=20,75,IF(P4>=15,60,IF(P4>=10,45,IF(P4>=5,30,15))))))),""),IFERROR(IF(Q4="","",IF(Q4>=40,100,IF(Q4>=30,90,IF(Q4>=20,75,IF(Q4>=10,60,IF(Q4>=5,45,IF(Q4>=0,30,15))))))),""),IFERROR(IF(R4="","",IF(R4>=40,100,IF(R4>=30,90,IF(R4>=20,75,IF(R4>=10,60,IF(R4>=0,45,IF(R4>=-10,30,15))))))),"")),"") | T4: 4 | U4: 4 | V4: 4 | W4: 4 | X4: 5 | Y4: =IFERROR((AVERAGE(T4,U4,V4,W4,X4)-1)*25,"") | Z4: 5 | AA4: 2 | AB4: 2 | AC4: 30.8 | AD4: =IFERROR(AVERAGE(IFERROR(IF(Z4="","",Z4*20),""),IFERROR(IF(AA4="","",AA4*20),""),IFERROR(IF(AB4="","",AB4*20),""),IFERROR(IF(AC4="","",IF(AC4>=85,100,IF(AC4>=70,90,IF(AC4>=55,75,IF(AC4>=40,60,IF(AC4>=25,40,20)))))),"")),"") | AE4: 4 | AF4: 4 | AG4: 4 | AH4: 5 | AI4: =IFERROR((AVERAGE(AE4,AF4,AG4,AH4,AL4)-1)*25,"") | AJ4: =IFERROR(J4*Weights!$B$4 + O4*Weights!$B$5 + S4*Weights!$B$6 + Y4*Weights!$B$7 + AD4*Weights!$B$8 + AI4*Weights!$B$9,"") | AK4: =IF(AJ4="","",IF(AJ4>=85,"✓✓✓",IF(AJ4>=70,"✓✓",IF(AJ4>=55,"✓",IF(AJ4>=40,"?","✗"))))) | AL4: 5
A5: GEV | B5: GE Vernova | C5: 02 Grid Equipment | D5: 2026-10-11 | E5: 39.759323 | F5: 65.627 | G5: 4.65 | H5: 6.4687634 | I5: =IF(OR(E5="",R5="",R5<=0,E5<0),"",E5/R5) | J5: 31.7 | K5: 7.22 | L5: 20.57 | M5: 30.07 | N5: -2.29 | O5: 58 | P5: 8.68 | Q5: 21.9 | S5: =IFERROR(AVERAGE(IFERROR(IF(P5="","",IF(P5>=40,100,IF(P5>=30,90,IF(P5>=20,75,IF(P5>=15,60,IF(P5>=10,45,IF(P5>=5,30,15))))))),""),IFERROR(IF(Q5="","",IF(Q5>=40,100,IF(Q5>=30,90,IF(Q5>=20,75,IF(Q5>=10,60,IF(Q5>=5,45,IF(Q5>=0,30,15))))))),""),IFERROR(IF(R5="","",IF(R5>=40,100,IF(R5>=30,90,IF(R5>=20,75,IF(R5>=10,60,IF(R5>=0,45,IF(R5>=-10,30,15))))))),"")),"") | T5: 2 | U5: 5 | V5: 5 | W5: 4 | X5: 5 | Y5: =IFERROR((AVERAGE(T5,U5,V5,W5,X5)-1)*25,"") | Z5: 4 | AA5: 4 | AB5: 4 | AC5: 49.2 | AD5: =IFERROR(AVERAGE(IFERROR(IF(Z5="","",Z5*20),""),IFERROR(IF(AA5="","",AA5*20),""),IFERROR(IF(AB5="","",AB5*20),""),IFERROR(IF(AC5="","",IF(AC5>=85,100,IF(AC5>=70,90,IF(AC5>=55,75,IF(AC5>=40,60,IF(AC5>=25,40,20)))))),"")),"") | AE5: 4 | AF5: 4 | AG5: 5 | AH5: 4 | AI5: =IFERROR((AVERAGE(AE5,AF5,AG5,AH5,AL5)-1)*25,"") | AJ5: =IFERROR(J5*Weights!$B$4 + O5*Weights!$B$5 + S5*Weights!$B$6 + Y5*Weights!$B$7 + AD5*Weights!$B$8 + AI5*Weights!$B$9,"") | AK5: =IF(AJ5="","",IF(AJ5>=85,"✓✓✓",IF(AJ5>=70,"✓✓",IF(AJ5>=55,"✓",IF(AJ5>=40,"?","✗"))))) | AL5: 5
A6: MU | B6: Micron Technology | C6: 06 Silicon - Memory | D6: 2026-10-11 | E6: 5.5325235 | F6: 10.944 | G6: 2.25 | H6: 8.741286 | I6: =IF(OR(E6="",R6="",R6<=0,E6<0),"",E6/R6) | J6: 60.3 | K6: 44.18 | L6: 80.72 | M6: 19.65 | N6: -0.35 | O6: 86.8 | P6: 6.71 | Q6: 379.3 | R6: 1077.8 | S6: =IFERROR(AVERAGE(IFERROR(IF(P6="","",IF(P6>=40,100,IF(P6>=30,90,IF(P6>=20,75,IF(P6>=15,60,IF(P6>=10,45,IF(P6>=5,30,15))))))),""),IFERROR(IF(Q6="","",IF(Q6>=40,100,IF(Q6>=30,90,IF(Q6>=20,75,IF(Q6>=10,60,IF(Q6>=5,45,IF(Q6>=0,30,15))))))),""),IFERROR(IF(R6="","",IF(R6>=40,100,IF(R6>=30,90,IF(R6>=20,75,IF(R6>=10,60,IF(R6>=0,45,IF(R6>=-10,30,15))))))),"")),"") | T6: 5 | U6: 4 | V6: 5 | W6: 5 | X6: 5 | Y6: =IFERROR((AVERAGE(T6,U6,V6,W6,X6)-1)*25,"") | Z6: 5 | AA6: 5 | AB6: 3 | AC6: 76.7 | AD6: =IFERROR(AVERAGE(IFERROR(IF(Z6="","",Z6*20),""),IFERROR(IF(AA6="","",AA6*20),""),IFERROR(IF(AB6="","",AB6*20),""),IFERROR(IF(AC6="","",IF(AC6>=85,100,IF(AC6>=70,90,IF(AC6>=55,75,IF(AC6>=40,60,IF(AC6>=25,40,20)))))),"")),"") | AE6: 3 | AF6: 2 | AG6: 5 | AH6: 3 | AI6: =IFERROR((AVERAGE(AE6,AF6,AG6,AH6,AL6)-1)*25,"") | AJ6: =IFERROR(J6*Weights!$B$4 + O6*Weights!$B$5 + S6*Weights!$B$6 + Y6*Weights!$B$7 + AD6*Weights!$B$8 + AI6*Weights!$B$9,"") | AK6: =IF(AJ6="","",IF(AJ6>=85,"✓✓✓",IF(AJ6>=70,"✓✓",IF(AJ6>=55,"✓",IF(AJ6>=40,"?","✗"))))) | AL6: 5
A7: CEG | B7: Constellation Energy Corporation | C7: 01 Power - IPP / Nuclear | D7: 2026-10-11 | E7: 22.37736 | F7: 16.41 | G7: 0.29 | H7: 3.3773074 | I7: =IF(OR(E7="",R7="",R7<=0,E7<0),"",E7/R7) | J7: 50.8 | K7: 3.56 | L7: 22.11 | M7: 0.99 | N7: 3.02 | O7: 44.3 | P7: 1.47 | Q7: 23 | S7: =IFERROR(AVERAGE(IFERROR(IF(P7="","",IF(P7>=40,100,IF(P7>=30,90,IF(P7>=20,75,IF(P7>=15,60,IF(P7>=10,45,IF(P7>=5,30,15))))))),""),IFERROR(IF(Q7="","",IF(Q7>=40,100,IF(Q7>=30,90,IF(Q7>=20,75,IF(Q7>=10,60,IF(Q7>=5,45,IF(Q7>=0,30,15))))))),""),IFERROR(IF(R7="","",IF(R7>=40,100,IF(R7>=30,90,IF(R7>=20,75,IF(R7>=10,60,IF(R7>=0,45,IF(R7>=-10,30,15))))))),"")),"") | T7: 2 | U7: 5 | V7: 4 | W7: 5 | X7: 5 | Y7: =IFERROR((AVERAGE(T7,U7,V7,W7,X7)-1)*25,"") | Z7: 3 | AA7: 2 | AB7: 3 | AC7: 40.8 | AD7: =IFERROR(AVERAGE(IFERROR(IF(Z7="","",Z7*20),""),IFERROR(IF(AA7="","",AA7*20),""),IFERROR(IF(AB7="","",AB7*20),""),IFERROR(IF(AC7="","",IF(AC7>=85,100,IF(AC7>=70,90,IF(AC7>=55,75,IF(AC7>=40,60,IF(AC7>=25,40,20)))))),"")),"") | AE7: 4 | AF7: 5 | AG7: 3 | AH7: 4 | AI7: =IFERROR((AVERAGE(AE7,AF7,AG7,AH7,AL7)-1)*25,"") | AJ7: =IFERROR(J7*Weights!$B$4 + O7*Weights!$B$5 + S7*Weights!$B$6 + Y7*Weights!$B$7 + AD7*Weights!$B$8 + AI7*Weights!$B$9,"") | AK7: =IF(AJ7="","",IF(AJ7>=85,"✓✓✓",IF(AJ7>=70,"✓✓",IF(AJ7>=55,"✓",IF(AJ7>=40,"?","✗"))))) | AL7: 5
A8: NVDA | B8: NVIDIA Corporation | C8: 06 AI Compute Silicon / GPUs / merchant accelerators | D8: 2026-10-11 | E8: 14.828233 | F8: 28.318 | G8: 2.29 | H8: 18.273836 | I8: =IF(OR(E8="",R8="",R8<=0,E8<0),"",E8/R8) | J8: 69.9 | K8: 59.83 | L8: 74.67 | M8: 41.92 | N8: -0.12 | O8: 92.5 | P8: 100.05 | Q8: 105.9 | R8: 125.9 | S8: =IFERROR(AVERAGE(IFERROR(IF(P8="","",IF(P8>=40,100,IF(P8>=30,90,IF(P8>=20,75,IF(P8>=15,60,IF(P8>=10,45,IF(P8>=5,30,15))))))),""),IFERROR(IF(Q8="","",IF(Q8>=40,100,IF(Q8>=30,90,IF(Q8>=20,75,IF(Q8>=10,60,IF(Q8>=5,45,IF(Q8>=0,30,15))))))),""),IFERROR(IF(R8="","",IF(R8>=40,100,IF(R8>=30,90,IF(R8>=20,75,IF(R8>=10,60,IF(R8>=0,45,IF(R8>=-10,30,15))))))),"")),"") | T8: 5 | U8: 5 | V8: 5 | W8: 5 | X8: 5 | Y8: =IFERROR((AVERAGE(T8,U8,V8,W8,X8)-1)*25,"") | Z8: 4 | AA8: 1 | AB8: 3 | AC8: 73.3 | AD8: =IFERROR(AVERAGE(IFERROR(IF(Z8="","",Z8*20),""),IFERROR(IF(AA8="","",AA8*20),""),IFERROR(IF(AB8="","",AB8*20),""),IFERROR(IF(AC8="","",IF(AC8>=85,100,IF(AC8>=70,90,IF(AC8>=55,75,IF(AC8>=40,60,IF(AC8>=25,40,20)))))),"")),"") | AE8: 4 | AF8: 2 | AG8: 5 | AH8: 3 | AI8: =IFERROR((AVERAGE(AE8,AF8,AG8,AH8,AL8)-1)*25,"") | AJ8: =IFERROR(J8*Weights!$B$4 + O8*Weights!$B$5 + S8*Weights!$B$6 + Y8*Weights!$B$7 + AD8*Weights!$B$8 + AI8*Weights!$B$9,"") | AK8: =IF(AJ8="","",IF(AJ8>=85,"✓✓✓",IF(AJ8>=70,"✓✓",IF(AJ8>=55,"✓",IF(AJ8>=40,"?","✗"))))) | AL8: 5
A9: AMD | B9: Advanced Micro Devices, Inc. | C9: 06 AI Compute Silicon / GPUs / merchant accelerators | D9: 2026-10-11 | E9: 38.678555 | F9: 109.341 | G9: 0.85 | H9: 24.033602 | I9: =IF(OR(E9="",R9="",R9<=0,E9<0),"",E9/R9) | J9: 34.4 | K9: 7.66 | L9: 55.72 | M9: 20.34 | N9: -0.92 | O9: 57.8 | P9: 13.64 | Q9: 50.1 | R9: 163.4 | S9: =IFERROR(AVERAGE(IFERROR(IF(P9="","",IF(P9>=40,100,IF(P9>=30,90,IF(P9>=20,75,IF(P9>=15,60,IF(P9>=10,45,IF(P9>=5,30,15))))))),""),IFERROR(IF(Q9="","",IF(Q9>=40,100,IF(Q9>=30,90,IF(Q9>=20,75,IF(Q9>=10,60,IF(Q9>=5,45,IF(Q9>=0,30,15))))))),""),IFERROR(IF(R9="","",IF(R9>=40,100,IF(R9>=30,90,IF(R9>=20,75,IF(R9>=10,60,IF(R9>=0,45,IF(R9>=-10,30,15))))))),"")),"") | T9: 4 | U9: 4 | V9: 5 | W9: 5 | X9: 5 | Y9: =IFERROR((AVERAGE(T9,U9,V9,W9,X9)-1)*25,"") | Z9: 5 | AA9: 5 | AB9: 3 | AC9: 75 | AD9: =IFERROR(AVERAGE(IFERROR(IF(Z9="","",Z9*20),""),IFERROR(IF(AA9="","",AA9*20),""),IFERROR(IF(AB9="","",AB9*20),""),IFERROR(IF(AC9="","",IF(AC9>=85,100,IF(AC9>=70,90,IF(AC9>=55,75,IF(AC9>=40,60,IF(AC9>=25,40,20)))))),"")),"") | AE9: 3 | AF9: 3 | AG9: 5 | AH9: 4 | AI9: =IFERROR((AVERAGE(AE9,AF9,AG9,AH9,AL9)-1)*25,"") | AJ9: =IFERROR(J9*Weights!$B$4 + O9*Weights!$B$5 + S9*Weights!$B$6 + Y9*Weights!$B$7 + AD9*Weights!$B$8 + AI9*Weights!$B$9,"") | AK9: =IF(AJ9="","",IF(AJ9>=85,"✓✓✓",IF(AJ9>=70,"✓✓",IF(AJ9>=55,"✓",IF(AJ9>=40,"?","✗"))))) | AL9: 5
A10: D | B10: Dominion Energy, Inc. | C10: 01 Power Generation / Regulated utilities (data-center geographic exposure) | D10: 2026-10-11 | E10: 16.160536 | F10: 13.599 | G10: -13.63 | H10: 2.9921067 | I10: =IF(OR(E10="",R10="",R10<=0,E10<0),"",E10/R10) | J10: 41.3 | K10: 4 | L10: 46.22 | M10: -40.79 | N10: 6.43 | O10: 39.2 | P10: 5.8 | Q10: 17.6 | R10: -55.3 | S10: =IFERROR(AVERAGE(IFERROR(IF(P10="","",IF(P10>=40,100,IF(P10>=30,90,IF(P10>=20,75,IF(P10>=15,60,IF(P10>=10,45,IF(P10>=5,30,15))))))),""),IFERROR(IF(Q10="","",IF(Q10>=40,100,IF(Q10>=30,90,IF(Q10>=20,75,IF(Q10>=10,60,IF(Q10>=5,45,IF(Q10>=0,30,15))))))),""),IFERROR(IF(R10="","",IF(R10>=40,100,IF(R10>=30,90,IF(R10>=20,75,IF(R10>=10,60,IF(R10>=0,45,IF(R10>=-10,30,15))))))),"")),"") | T10: 2 | U10: 3 | V10: 4 | W10: 5 | X10: 3 | Y10: =IFERROR((AVERAGE(T10,U10,V10,W10,X10)-1)*25,"") | Z10: 3 | AA10: 4 | AB10: 3 | AC10: 52.5 | AD10: =IFERROR(AVERAGE(IFERROR(IF(Z10="","",Z10*20),""),IFERROR(IF(AA10="","",AA10*20),""),IFERROR(IF(AB10="","",AB10*20),""),IFERROR(IF(AC10="","",IF(AC10>=85,100,IF(AC10>=70,90,IF(AC10>=55,75,IF(AC10>=40,60,IF(AC10>=25,40,20)))))),"")),"") | AE10: 5 | AF10: 5 | AG10: 3 | AH10: 2 | AI10: =IFERROR((AVERAGE(AE10,AF10,AG10,AH10,AL10)-1)*25,"") | AJ10: =IFERROR(J10*Weights!$B$4 + O10*Weights!$B$5 + S10*Weights!$B$6 + Y10*Weights!$B$7 + AD10*Weights!$B$8 + AI10*Weights!$B$9,"") | AK10: =IF(AJ10="","",IF(AJ10>=85,"✓✓✓",IF(AJ10>=70,"✓✓",IF(AJ10>=55,"✓",IF(AJ10>=40,"?","✗"))))) | AL10: 5
A11: AEP | B11: American Electric Power Company, Inc. | C11: 01 Power Generation / Regulated utilities (data-center geographic exposure) | D11: 2026-10-11 | E11: 17.910582 | F11: 13.356 | G11: -3.65 | H11: 2.9335017 | I11: =IF(OR(E11="",R11="",R11<=0,E11<0),"",E11/R11) | J11: 49.5 | K11: 4.47 | L11: 46.35 | M11: -10.69 | N11: 5.86 | O11: 43.9 | P11: 3.66 | Q11: 7 | R11: -41.8 | S11: =IFERROR(AVERAGE(IFERROR(IF(P11="","",IF(P11>=40,100,IF(P11>=30,90,IF(P11>=20,75,IF(P11>=15,60,IF(P11>=10,45,IF(P11>=5,30,15))))))),""),IFERROR(IF(Q11="","",IF(Q11>=40,100,IF(Q11>=30,90,IF(Q11>=20,75,IF(Q11>=10,60,IF(Q11>=5,45,IF(Q11>=0,30,15))))))),""),IFERROR(IF(R11="","",IF(R11>=40,100,IF(R11>=30,90,IF(R11>=20,75,IF(R11>=10,60,IF(R11>=0,45,IF(R11>=-10,30,15))))))),"")),"") | T11: 1 | U11: 3 | V11: 4 | W11: 5 | X11: 3 | Y11: =IFERROR((AVERAGE(T11,U11,V11,W11,X11)-1)*25,"") | Z11: 5 | AA11: 4 | AB11: 3 | AC11: 30.8 | AD11: =IFERROR(AVERAGE(IFERROR(IF(Z11="","",Z11*20),""),IFERROR(IF(AA11="","",AA11*20),""),IFERROR(IF(AB11="","",AB11*20),""),IFERROR(IF(AC11="","",IF(AC11>=85,100,IF(AC11>=70,90,IF(AC11>=55,75,IF(AC11>=40,60,IF(AC11>=25,40,20)))))),"")),"") | AE11: 5 | AF11: 5 | AG11: 3 | AH11: 4 | AI11: =IFERROR((AVERAGE(AE11,AF11,AG11,AH11,AL11)-1)*25,"") | AJ11: =IFERROR(J11*Weights!$B$4 + O11*Weights!$B$5 + S11*Weights!$B$6 + Y11*Weights!$B$7 + AD11*Weights!$B$8 + AI11*Weights!$B$9,"") | AK11: =IF(AJ11="","",IF(AJ11>=85,"✓✓✓",IF(AJ11>=70,"✓✓",IF(AJ11>=55,"✓",IF(AJ11>=40,"?","✗"))))) | AL11: 5
A12: DUK | B12: Duke Energy Corporation | C12: 01 Power Generation / Regulated utilities (data-center geographic exposure) | D12: 2026-10-11 | E12: 16.265955 | F12: 11.114 | G12: -3.63 | H12: 2.7726812 | I12: =IF(OR(E12="",R12="",R12<=0,E12<0),"",E12/R12) | J12: 60.5 | K12: 4.2 | L12: 51.97 | M12: -10.06 | N12: 5.51 | O12: 47.1 | P12: 3.87 | Q12: 1.1 | R12: 11 | S12: =IFERROR(AVERAGE(IFERROR(IF(P12="","",IF(P12>=40,100,IF(P12>=30,90,IF(P12>=20,75,IF(P12>=15,60,IF(P12>=10,45,IF(P12>=5,30,15))))))),""),IFERROR(IF(Q12="","",IF(Q12>=40,100,IF(Q12>=30,90,IF(Q12>=20,75,IF(Q12>=10,60,IF(Q12>=5,45,IF(Q12>=0,30,15))))))),""),IFERROR(IF(R12="","",IF(R12>=40,100,IF(R12>=30,90,IF(R12>=20,75,IF(R12>=10,60,IF(R12>=0,45,IF(R12>=-10,30,15))))))),"")),"") | T12: 1 | U12: 3 | V12: 4 | W12: 5 | X12: 3 | Y12: =IFERROR((AVERAGE(T12,U12,V12,W12,X12)-1)*25,"") | Z12: 4 | AA12: 3 | AB12: 3 | AC12: 22.5 | AD12: =IFERROR(AVERAGE(IFERROR(IF(Z12="","",Z12*20),""),IFERROR(IF(AA12="","",AA12*20),""),IFERROR(IF(AB12="","",AB12*20),""),IFERROR(IF(AC12="","",IF(AC12>=85,100,IF(AC12>=70,90,IF(AC12>=55,75,IF(AC12>=40,60,IF(AC12>=25,40,20)))))),"")),"") | AE12: 5 | AF12: 5 | AG12: 3 | AH12: 4 | AI12: =IFERROR((AVERAGE(AE12,AF12,AG12,AH12,AL12)-1)*25,"") | AJ12: =IFERROR(J12*Weights!$B$4 + O12*Weights!$B$5 + S12*Weights!$B$6 + Y12*Weights!$B$7 + AD12*Weights!$B$8 + AI12*Weights!$B$9,"") | AK12: =IF(AJ12="","",IF(AJ12>=85,"✓✓✓",IF(AJ12>=70,"✓✓",IF(AJ12>=55,"✓",IF(AJ12>=40,"?","✗"))))) | AL12: 5
A13: SO | B13: The Southern Company | C13: 01 Power Generation / Regulated utilities (data-center geographic exposure) | D13: 2026-10-11 | E13: 17.502808 | F13: 12.285 | G13: -3.3 | H13: 3.2846277 | I13: =IF(OR(E13="",R13="",R13<=0,E13<0),"",E13/R13) | J13: 44.6 | K13: 4.35 | L13: 48.29 | M13: -10.83 | N13: 5.2 | O13: 47.1 | P13: 0.31 | Q13: 0.1 | R13: 33.4 | S13: =IFERROR(AVERAGE(IFERROR(IF(P13="","",IF(P13>=40,100,IF(P13>=30,90,IF(P13>=20,75,IF(P13>=15,60,IF(P13>=10,45,IF(P13>=5,30,15))))))),""),IFERROR(IF(Q13="","",IF(Q13>=40,100,IF(Q13>=30,90,IF(Q13>=20,75,IF(Q13>=10,60,IF(Q13>=5,45,IF(Q13>=0,30,15))))))),""),IFERROR(IF(R13="","",IF(R13>=40,100,IF(R13>=30,90,IF(R13>=20,75,IF(R13>=10,60,IF(R13>=0,45,IF(R13>=-10,30,15))))))),"")),"") | T13: 1 | U13: 3 | V13: 4 | W13: 5 | X13: 3 | Y13: =IFERROR((AVERAGE(T13,U13,V13,W13,X13)-1)*25,"") | Z13: 2 | AA13: 4 | AB13: 3 | AC13: 29.2 | AD13: =IFERROR(AVERAGE(IFERROR(IF(Z13="","",Z13*20),""),IFERROR(IF(AA13="","",AA13*20),""),IFERROR(IF(AB13="","",AB13*20),""),IFERROR(IF(AC13="","",IF(AC13>=85,100,IF(AC13>=70,90,IF(AC13>=55,75,IF(AC13>=40,60,IF(AC13>=25,40,20)))))),"")),"") | AE13: 5 | AF13: 5 | AG13: 3 | AH13: 4 | AI13: =IFERROR((AVERAGE(AE13,AF13,AG13,AH13,AL13)-1)*25,"") | AJ13: =IFERROR(J13*Weights!$B$4 + O13*Weights!$B$5 + S13*Weights!$B$6 + Y13*Weights!$B$7 + AD13*Weights!$B$8 + AI13*Weights!$B$9,"") | AK13: =IF(AJ13="","",IF(AJ13>=85,"✓✓✓",IF(AJ13>=70,"✓✓",IF(AJ13>=55,"✓",IF(AJ13>=40,"?","✗"))))) | AL13: 5
A14: NEE | B14: NextEra Energy, Inc. | C14: 01 Power Generation / Regulated utilities (data-center geographic exposure) | D14: 2026-10-11 | E14: 17.68144 | F14: 19.125 | G14: 1.89 | H14: 5.623141 | I14: =IF(OR(E14="",R14="",R14<=0,E14<0),"",E14/R14) | J14: 46.9 | K14: 3.99 | L14: 61.02 | M14: 10.62 | N14: 7.35 | O14: 54.4 | P14: 9.36 | Q14: 12.4 | R14: 55 | S14: =IFERROR(AVERAGE(IFERROR(IF(P14="","",IF(P14>=40,100,IF(P14>=30,90,IF(P14>=20,75,IF(P14>=15,60,IF(P14>=10,45,IF(P14>=5,30,15))))))),""),IFERROR(IF(Q14="","",IF(Q14>=40,100,IF(Q14>=30,90,IF(Q14>=20,75,IF(Q14>=10,60,IF(Q14>=5,45,IF(Q14>=0,30,15))))))),""),IFERROR(IF(R14="","",IF(R14>=40,100,IF(R14>=30,90,IF(R14>=20,75,IF(R14>=10,60,IF(R14>=0,45,IF(R14>=-10,30,15))))))),"")),"") | T14: 2 | U14: 4 | V14: 5 | W14: 5 | X14: 5 | Y14: =IFERROR((AVERAGE(T14,U14,V14,W14,X14)-1)*25,"") | Z14: 4 | AA14: 3 | AB14: 3 | AC14: 25.8 | AD14: =IFERROR(AVERAGE(IFERROR(IF(Z14="","",Z14*20),""),IFERROR(IF(AA14="","",AA14*20),""),IFERROR(IF(AB14="","",AB14*20),""),IFERROR(IF(AC14="","",IF(AC14>=85,100,IF(AC14>=70,90,IF(AC14>=55,75,IF(AC14>=40,60,IF(AC14>=25,40,20)))))),"")),"") | AE14: 5 | AF14: 5 | AG14: 3 | AH14: 2 | AI14: =IFERROR((AVERAGE(AE14,AF14,AG14,AH14,AL14)-1)*25,"") | AJ14: =IFERROR(J14*Weights!$B$4 + O14*Weights!$B$5 + S14*Weights!$B$6 + Y14*Weights!$B$7 + AD14*Weights!$B$8 + AI14*Weights!$B$9,"") | AK14: =IF(AJ14="","",IF(AJ14>=85,"✓✓✓",IF(AJ14>=70,"✓✓",IF(AJ14>=55,"✓",IF(AJ14>=40,"?","✗"))))) | AL14: 5
A15: ETR | B15: Entergy Corporation | C15: 01 Power Generation / Regulated utilities (data-center geographic exposure) | D15: 2026-10-11 | E15: 20.139488 | F15: 14.274 | G15: -6.42 | H15: 3.6429832 | I15: =IF(OR(E15="",R15="",R15<=0,E15<0),"",E15/R15) | J15: 34.2 | K15: 3.62 | L15: 47 | M15: -23.37 | N15: 5.56 | O15: 35.5 | P15: -2.02 | Q15: 5.9 | R15: 3.1 | S15: =IFERROR(AVERAGE(IFERROR(IF(P15="","",IF(P15>=40,100,IF(P15>=30,90,IF(P15>=20,75,IF(P15>=15,60,IF(P15>=10,45,IF(P15>=5,30,15))))))),""),IFERROR(IF(Q15="","",IF(Q15>=40,100,IF(Q15>=30,90,IF(Q15>=20,75,IF(Q15>=10,60,IF(Q15>=5,45,IF(Q15>=0,30,15))))))),""),IFERROR(IF(R15="","",IF(R15>=40,100,IF(R15>=30,90,IF(R15>=20,75,IF(R15>=10,60,IF(R15>=0,45,IF(R15>=-10,30,15))))))),"")),"") | T15: 1 | U15: 3 | V15: 4 | W15: 5 | X15: 3 | Y15: =IFERROR((AVERAGE(T15,U15,V15,W15,X15)-1)*25,"") | Z15: 5 | AA15: 4 | AB15: 3 | AC15: 40 | AD15: =IFERROR(AVERAGE(IFERROR(IF(Z15="","",Z15*20),""),IFERROR(IF(AA15="","",AA15*20),""),IFERROR(IF(AB15="","",AB15*20),""),IFERROR(IF(AC15="","",IF(AC15>=85,100,IF(AC15>=70,90,IF(AC15>=55,75,IF(AC15>=40,60,IF(AC15>=25,40,20)))))),"")),"") | AE15: 5 | AF15: 5 | AG15: 3 | AH15: 4 | AI15: =IFERROR((AVERAGE(AE15,AF15,AG15,AH15,AL15)-1)*25,"") | AJ15: =IFERROR(J15*Weights!$B$4 + O15*Weights!$B$5 + S15*Weights!$B$6 + Y15*Weights!$B$7 + AD15*Weights!$B$8 + AI15*Weights!$B$9,"") | AK15: =IF(AJ15="","",IF(AJ15>=85,"✓✓✓",IF(AJ15>=70,"✓✓",IF(AJ15>=55,"✓",IF(AJ15>=40,"?","✗"))))) | AL15: 5
A16: PPL | B16: PPL Corporation | C16: 01 Power Generation / Regulated utilities (data-center geographic exposure) | D16: 2026-10-11 | E16: 16.162142 | F16: 12.129 | G16: -7.73 | H16: 2.7425687 | I16: =IF(OR(E16="",R16="",R16<=0,E16<0),"",E16/R16) | J16: 54.5 | K16: 4.26 | L16: 44.09 | M16: -21.2 | N16: 5.33 | O16: 38.6 | P16: 4.59 | Q16: 4.2 | R16: 25.7 | S16: =IFERROR(AVERAGE(IFERROR(IF(P16="","",IF(P16>=40,100,IF(P16>=30,90,IF(P16>=20,75,IF(P16>=15,60,IF(P16>=10,45,IF(P16>=5,30,15))))))),""),IFERROR(IF(Q16="","",IF(Q16>=40,100,IF(Q16>=30,90,IF(Q16>=20,75,IF(Q16>=10,60,IF(Q16>=5,45,IF(Q16>=0,30,15))))))),""),IFERROR(IF(R16="","",IF(R16>=40,100,IF(R16>=30,90,IF(R16>=20,75,IF(R16>=10,60,IF(R16>=0,45,IF(R16>=-10,30,15))))))),"")),"") | T16: 1 | U16: 3 | V16: 4 | W16: 5 | X16: 3 | Y16: =IFERROR((AVERAGE(T16,U16,V16,W16,X16)-1)*25,"") | Z16: 4 | AA16: 3 | AB16: 3 | AC16: 22.5 | AD16: =IFERROR(AVERAGE(IFERROR(IF(Z16="","",Z16*20),""),IFERROR(IF(AA16="","",AA16*20),""),IFERROR(IF(AB16="","",AB16*20),""),IFERROR(IF(AC16="","",IF(AC16>=85,100,IF(AC16>=70,90,IF(AC16>=55,75,IF(AC16>=40,60,IF(AC16>=25,40,20)))))),"")),"") | AE16: 5 | AF16: 5 | AG16: 3 | AH16: 4 | AI16: =IFERROR((AVERAGE(AE16,AF16,AG16,AH16,AL16)-1)*25,"") | AJ16: =IFERROR(J16*Weights!$B$4 + O16*Weights!$B$5 + S16*Weights!$B$6 + Y16*Weights!$B$7 + AD16*Weights!$B$8 + AI16*Weights!$B$9,"") | AK16: =IF(AJ16="","",IF(AJ16>=85,"✓✓✓",IF(AJ16>=70,"✓✓",IF(AJ16>=55,"✓",IF(AJ16>=40,"?","✗"))))) | AL16: 5
A17: XEL | B17: Xcel Energy Inc. | C17: 01 Power Generation / Regulated utilities (data-center geographic exposure) | D17: 2026-10-11 | E17: 16.258345 | F17: 13.861 | G17: -16.69 | H17: 3.1528733 | I17: =IF(OR(E17="",R17="",R17<=0,E17<0),"",E17/R17) | J17: 49.3 | K17: 3.91 | L17: 46.83 | M17: -52.63 | N17: 6.47 | O17: 33.9 | P17: -1.42 | Q17: -5.1 | R17: 32 | S17: =IFERROR(AVERAGE(IFERROR(IF(P17="","",IF(P17>=40,100,IF(P17>=30,90,IF(P17>=20,75,IF(P17>=15,60,IF(P17>=10,45,IF(P17>=5,30,15))))))),""),IFERROR(IF(Q17="","",IF(Q17>=40,100,IF(Q17>=30,90,IF(Q17>=20,75,IF(Q17>=10,60,IF(Q17>=5,45,IF(Q17>=0,30,15))))))),""),IFERROR(IF(R17="","",IF(R17>=40,100,IF(R17>=30,90,IF(R17>=20,75,IF(R17>=10,60,IF(R17>=0,45,IF(R17>=-10,30,15))))))),"")),"") | T17: 1 | U17: 3 | V17: 4 | W17: 4 | X17: 3 | Y17: =IFERROR((AVERAGE(T17,U17,V17,W17,X17)-1)*25,"") | Z17: 4 | AA17: 3 | AB17: 3 | AC17: 27.5 | AD17: =IFERROR(AVERAGE(IFERROR(IF(Z17="","",Z17*20),""),IFERROR(IF(AA17="","",AA17*20),""),IFERROR(IF(AB17="","",AB17*20),""),IFERROR(IF(AC17="","",IF(AC17>=85,100,IF(AC17>=70,90,IF(AC17>=55,75,IF(AC17>=40,60,IF(AC17>=25,40,20)))))),"")),"") | AE17: 5 | AF17: 5 | AG17: 3 | AH17: 4 | AI17: =IFERROR((AVERAGE(AE17,AF17,AG17,AH17,AL17)-1)*25,"") | AJ17: =IFERROR(J17*Weights!$B$4 + O17*Weights!$B$5 + S17*Weights!$B$6 + Y17*Weights!$B$7 + AD17*Weights!$B$8 + AI17*Weights!$B$9,"") | AK17: =IF(AJ17="","",IF(AJ17>=85,"✓✓✓",IF(AJ17>=70,"✓✓",IF(AJ17>=55,"✓",IF(AJ17>=40,"?","✗"))))) | AL17: 5
A18: VST | B18: Vistra Corp. | C18: 01 Power Generation / Independent Power Producers (IPPs) | D18: 2026-10-11 | E18: 15.502566 | F18: 11.814 | G18: 4.16 | H18: 2.8210688 | I18: =IF(OR(E18="",R18="",R18<=0,E18<0),"",E18/R18) | J18: 71.6 | K18: 9.2 | L18: 38.31 | M18: 11.74 | N18: 3.02 | O18: 65.1 | P18: 8.92 | Q18: -5.5 | S18: =IFERROR(AVERAGE(IFERROR(IF(P18="","",IF(P18>=40,100,IF(P18>=30,90,IF(P18>=20,75,IF(P18>=15,60,IF(P18>=10,45,IF(P18>=5,30,15))))))),""),IFERROR(IF(Q18="","",IF(Q18>=40,100,IF(Q18>=30,90,IF(Q18>=20,75,IF(Q18>=10,60,IF(Q18>=5,45,IF(Q18>=0,30,15))))))),""),IFERROR(IF(R18="","",IF(R18>=40,100,IF(R18>=30,90,IF(R18>=20,75,IF(R18>=10,60,IF(R18>=0,45,IF(R18>=-10,30,15))))))),"")),"") | T18: 2 | U18: 5 | V18: 5 | W18: 5 | X18: 5 | Y18: =IFERROR((AVERAGE(T18,U18,V18,W18,X18)-1)*25,"") | Z18: 4 | AA18: 1 | AB18: 3 | AC18: 36.7 | AD18: =IFERROR(AVERAGE(IFERROR(IF(Z18="","",Z18*20),""),IFERROR(IF(AA18="","",AA18*20),""),IFERROR(IF(AB18="","",AB18*20),""),IFERROR(IF(AC18="","",IF(AC18>=85,100,IF(AC18>=70,90,IF(AC18>=55,75,IF(AC18>=40,60,IF(AC18>=25,40,20)))))),"")),"") | AE18: 4 | AF18: 5 | AG18: 4 | AH18: 4 | AI18: =IFERROR((AVERAGE(AE18,AF18,AG18,AH18,AL18)-1)*25,"") | AJ18: =IFERROR(J18*Weights!$B$4 + O18*Weights!$B$5 + S18*Weights!$B$6 + Y18*Weights!$B$7 + AD18*Weights!$B$8 + AI18*Weights!$B$9,"") | AK18: =IF(AJ18="","",IF(AJ18>=85,"✓✓✓",IF(AJ18>=70,"✓✓",IF(AJ18>=55,"✓",IF(AJ18>=40,"?","✗"))))) | AL18: 5
A19: TLN | B19: Talen Energy Corporation | C19: 01 Power Generation / Independent Power Producers (IPPs) | D19: 2026-10-11 | E19: 12.30933 | F19: 47.237 | G19: 2.48 | H19: 4.7865176 | I19: =IF(OR(E19="",R19="",R19<=0,E19<0),"",E19/R19) | J19: 49.5 | K19: 2.69 | L19: 42.1 | M19: 11.87 | N19: 16.05 | O19: 47.1 | P19: 13.95 | Q19: 111.2 | S19: =IFERROR(AVERAGE(IFERROR(IF(P19="","",IF(P19>=40,100,IF(P19>=30,90,IF(P19>=20,75,IF(P19>=15,60,IF(P19>=10,45,IF(P19>=5,30,15))))))),""),IFERROR(IF(Q19="","",IF(Q19>=40,100,IF(Q19>=30,90,IF(Q19>=20,75,IF(Q19>=10,60,IF(Q19>=5,45,IF(Q19>=0,30,15))))))),""),IFERROR(IF(R19="","",IF(R19>=40,100,IF(R19>=30,90,IF(R19>=20,75,IF(R19>=10,60,IF(R19>=0,45,IF(R19>=-10,30,15))))))),"")),"") | T19: 2 | U19: 5 | V19: 5 | W19: 5 | X19: 4 | Y19: =IFERROR((AVERAGE(T19,U19,V19,W19,X19)-1)*25,"") | Z19: 4 | AA19: 2 | AB19: 3 | AC19: 47.5 | AD19: =IFERROR(AVERAGE(IFERROR(IF(Z19="","",Z19*20),""),IFERROR(IF(AA19="","",AA19*20),""),IFERROR(IF(AB19="","",AB19*20),""),IFERROR(IF(AC19="","",IF(AC19>=85,100,IF(AC19>=70,90,IF(AC19>=55,75,IF(AC19>=40,60,IF(AC19>=25,40,20)))))),"")),"") | AE19: 3 | AF19: 5 | AG19: 2 | AH19: 4 | AI19: =IFERROR((AVERAGE(AE19,AF19,AG19,AH19,AL19)-1)*25,"") | AJ19: =IFERROR(J19*Weights!$B$4 + O19*Weights!$B$5 + S19*Weights!$B$6 + Y19*Weights!$B$7 + AD19*Weights!$B$8 + AI19*Weights!$B$9,"") | AK19: =IF(AJ19="","",IF(AJ19>=85,"✓✓✓",IF(AJ19>=70,"✓✓",IF(AJ19>=55,"✓",IF(AJ19>=40,"?","✗"))))) | AL19: 5
A20: NRG | B20: NRG Energy, Inc. | C20: 01 Power Generation / Independent Power Producers (IPPs) | D20: 2026-10-11 | E20: 9.649501 | F20: 14.382 | G20: 1.39 | H20: 0.6851751 | I20: =IF(OR(E20="",R20="",R20<=0,E20<0),"",E20/R20) | J20: 55.4 | K20: 5.62 | L20: 18.8 | M20: 0.95 | N20: 7.16 | O20: 35.9 | P20: -0.88 | Q20: 11 | R20: -83.3 | S20: =IFERROR(AVERAGE(IFERROR(IF(P20="","",IF(P20>=40,100,IF(P20>=30,90,IF(P20>=20,75,IF(P20>=15,60,IF(P20>=10,45,IF(P20>=5,30,15))))))),""),IFERROR(IF(Q20="","",IF(Q20>=40,100,IF(Q20>=30,90,IF(Q20>=20,75,IF(Q20>=10,60,IF(Q20>=5,45,IF(Q20>=0,30,15))))))),""),IFERROR(IF(R20="","",IF(R20>=40,100,IF(R20>=30,90,IF(R20>=20,75,IF(R20>=10,60,IF(R20>=0,45,IF(R20>=-10,30,15))))))),"")),"") | T20: 1 | U20: 3 | V20: 3 | W20: 4 | X20: 2 | Y20: =IFERROR((AVERAGE(T20,U20,V20,W20,X20)-1)*25,"") | Z20: 5 | AA20: 1 | AB20: 3 | AC20: 14.2 | AD20: =IFERROR(AVERAGE(IFERROR(IF(Z20="","",Z20*20),""),IFERROR(IF(AA20="","",AA20*20),""),IFERROR(IF(AB20="","",AB20*20),""),IFERROR(IF(AC20="","",IF(AC20>=85,100,IF(AC20>=70,90,IF(AC20>=55,75,IF(AC20>=40,60,IF(AC20>=25,40,20)))))),"")),"") | AE20: 4 | AF20: 5 | AG20: 3 | AH20: 4 | AI20: =IFERROR((AVERAGE(AE20,AF20,AG20,AH20,AL20)-1)*25,"") | AJ20: =IFERROR(J20*Weights!$B$4 + O20*Weights!$B$5 + S20*Weights!$B$6 + Y20*Weights!$B$7 + AD20*Weights!$B$8 + AI20*Weights!$B$9,"") | AK20: =IF(AJ20="","",IF(AJ20>=85,"✓✓✓",IF(AJ20>=70,"✓✓",IF(AJ20>=55,"✓",IF(AJ20>=40,"?","✗"))))) | AL20: 5
A21: CCJ | B21: Cameco Corporation | C21: 01 Power Generation / Nuclear-specific | D21: 2026-10-11 | E21: 48.468468 | F21: 68.59 | G21: 1.69 | H21: 15.73 | I21: =IF(OR(E21="",R21="",R21<=0,E21<0),"",E21/R21) | J21: 39.6 | K21: 5.16 | L21: 35.11 | M21: 26.53 | N21: 0.14 | O21: 76 | P21: 23.07 | Q21: -7.2 | R21: -92.1 | S21: =IFERROR(AVERAGE(IFERROR(IF(P21="","",IF(P21>=40,100,IF(P21>=30,90,IF(P21>=20,75,IF(P21>=15,60,IF(P21>=10,45,IF(P21>=5,30,15))))))),""),IFERROR(IF(Q21="","",IF(Q21>=40,100,IF(Q21>=30,90,IF(Q21>=20,75,IF(Q21>=10,60,IF(Q21>=5,45,IF(Q21>=0,30,15))))))),""),IFERROR(IF(R21="","",IF(R21>=40,100,IF(R21>=30,90,IF(R21>=20,75,IF(R21>=10,60,IF(R21>=0,45,IF(R21>=-10,30,15))))))),"")),"") | T21: 1 | U21: 4 | V21: 4 | W21: 4 | X21: 2 | Y21: =IFERROR((AVERAGE(T21,U21,V21,W21,X21)-1)*25,"") | Z21: 4 | AA21: 2 | AB21: 3 | AC21: 31.7 | AD21: =IFERROR(AVERAGE(IFERROR(IF(Z21="","",Z21*20),""),IFERROR(IF(AA21="","",AA21*20),""),IFERROR(IF(AB21="","",AB21*20),""),IFERROR(IF(AC21="","",IF(AC21>=85,100,IF(AC21>=70,90,IF(AC21>=55,75,IF(AC21>=40,60,IF(AC21>=25,40,20)))))),"")),"") | AE21: 5 | AF21: 4 | AG21: 5 | AH21: 4 | AI21: =IFERROR((AVERAGE(AE21,AF21,AG21,AH21,AL21)-1)*25,"") | AJ21: =IFERROR(J21*Weights!$B$4 + O21*Weights!$B$5 + S21*Weights!$B$6 + Y21*Weights!$B$7 + AD21*Weights!$B$8 + AI21*Weights!$B$9,"") | AK21: =IF(AJ21="","",IF(AJ21>=85,"✓✓✓",IF(AJ21>=70,"✓✓",IF(AJ21>=55,"✓",IF(AJ21>=40,"?","✗"))))) | AL21: 5
A22: UEC | B22: Uranium Energy Corp. | C22: 01 Power Generation / Nuclear-specific | D22: 2026-10-11 | E22: -124.18918 | F22: -33.279 | G22: -2.64 | H22: 122.26638 | I22: =IF(OR(E22="",R22="",R22<=0,E22<0),"",E22/R22) | J22: 35.7 | K22: -6.61 | L22: -183.96 | M22: -322.78 | O22: 8.7 | P22: 42.37 | Q22: -59.4 | S22: =IFERROR(AVERAGE(IFERROR(IF(P22="","",IF(P22>=40,100,IF(P22>=30,90,IF(P22>=20,75,IF(P22>=15,60,IF(P22>=10,45,IF(P22>=5,30,15))))))),""),IFERROR(IF(Q22="","",IF(Q22>=40,100,IF(Q22>=30,90,IF(Q22>=20,75,IF(Q22>=10,60,IF(Q22>=5,45,IF(Q22>=0,30,15))))))),""),IFERROR(IF(R22="","",IF(R22>=40,100,IF(R22>=30,90,IF(R22>=20,75,IF(R22>=10,60,IF(R22>=0,45,IF(R22>=-10,30,15))))))),"")),"") | T22: 1 | U22: 2 | V22: 4 | W22: 4 | X22: 1 | Y22: =IFERROR((AVERAGE(T22,U22,V22,W22,X22)-1)*25,"") | Z22: 2 | AA22: 1 | AB22: 3 | AC22: 34.2 | AD22: =IFERROR(AVERAGE(IFERROR(IF(Z22="","",Z22*20),""),IFERROR(IF(AA22="","",AA22*20),""),IFERROR(IF(AB22="","",AB22*20),""),IFERROR(IF(AC22="","",IF(AC22>=85,100,IF(AC22>=70,90,IF(AC22>=55,75,IF(AC22>=40,60,IF(AC22>=25,40,20)))))),"")),"") | AE22: 4 | AF22: 5 | AG22: 5 | AH22: 4 | AI22: =IFERROR((AVERAGE(AE22,AF22,AG22,AH22,AL22)-1)*25,"") | AJ22: =IFERROR(J22*Weights!$B$4 + O22*Weights!$B$5 + S22*Weights!$B$6 + Y22*Weights!$B$7 + AD22*Weights!$B$8 + AI22*Weights!$B$9,"") | AK22: =IF(AJ22="","",IF(AJ22>=85,"✓✓✓",IF(AJ22>=70,"✓✓",IF(AJ22>=55,"✓",IF(AJ22>=40,"?","✗"))))) | AL22: 5
A23: LEU | B23: Centrus Energy Corp. | C23: 01 Power Generation / Nuclear-specific | D23: 2026-10-11 | E23: 37.26289 | F23: 222.264 | G23: -5.62 | H23: 6.1475854 | I23: =IF(OR(E23="",R23="",R23<=0,E23<0),"",E23/R23) | J23: 26.1 | K23: 0.35 | L23: 23.66 | M23: -34.56 | N23: -68.42 | O23: 48.6 | P23: 15.16 | Q23: 14 | R23: -41.9 | S23: =IFERROR(AVERAGE(IFERROR(IF(P23="","",IF(P23>=40,100,IF(P23>=30,90,IF(P23>=20,75,IF(P23>=15,60,IF(P23>=10,45,IF(P23>=5,30,15))))))),""),IFERROR(IF(Q23="","",IF(Q23>=40,100,IF(Q23>=30,90,IF(Q23>=20,75,IF(Q23>=10,60,IF(Q23>=5,45,IF(Q23>=0,30,15))))))),""),IFERROR(IF(R23="","",IF(R23>=40,100,IF(R23>=30,90,IF(R23>=20,75,IF(R23>=10,60,IF(R23>=0,45,IF(R23>=-10,30,15))))))),"")),"") | T23: 1 | U23: 4 | V23: 4 | W23: 5 | X23: 3 | Y23: =IFERROR((AVERAGE(T23,U23,V23,W23,X23)-1)*25,"") | Z23: 3 | AA23: 1 | AB23: 3 | AC23: 35 | AD23: =IFERROR(AVERAGE(IFERROR(IF(Z23="","",Z23*20),""),IFERROR(IF(AA23="","",AA23*20),""),IFERROR(IF(AB23="","",AB23*20),""),IFERROR(IF(AC23="","",IF(AC23>=85,100,IF(AC23>=70,90,IF(AC23>=55,75,IF(AC23>=40,60,IF(AC23>=25,40,20)))))),"")),"") | AE23: 4 | AF23: 5 | AG23: 4 | AH23: 4 | AI23: =IFERROR((AVERAGE(AE23,AF23,AG23,AH23,AL23)-1)*25,"") | AJ23: =IFERROR(J23*Weights!$B$4 + O23*Weights!$B$5 + S23*Weights!$B$6 + Y23*Weights!$B$7 + AD23*Weights!$B$8 + AI23*Weights!$B$9,"") | AK23: =IF(AJ23="","",IF(AJ23>=85,"✓✓✓",IF(AJ23>=70,"✓✓",IF(AJ23>=55,"✓",IF(AJ23>=40,"?","✗"))))) | AL23: 5
A24: BWXT | B24: BWX Technologies, Inc. | C24: 01 Power Generation / Nuclear-specific | D24: 2026-10-11 | E24: 27.50027 | F24: 30.178 | G24: 2.4 | H24: 3.7501717 | I24: =IF(OR(E24="",R24="",R24<=0,E24<0),"",E24/R24) | J24: 38.3 | K24: 7.6 | L24: 22.08 | M24: 9.01 | N24: 2.96 | O24: 54.4 | P24: 12.73 | Q24: 18 | R24: 13.6 | S24: =IFERROR(AVERAGE(IFERROR(IF(P24="","",IF(P24>=40,100,IF(P24>=30,90,IF(P24>=20,75,IF(P24>=15,60,IF(P24>=10,45,IF(P24>=5,30,15))))))),""),IFERROR(IF(Q24="","",IF(Q24>=40,100,IF(Q24>=30,90,IF(Q24>=20,75,IF(Q24>=10,60,IF(Q24>=5,45,IF(Q24>=0,30,15))))))),""),IFERROR(IF(R24="","",IF(R24>=40,100,IF(R24>=30,90,IF(R24>=20,75,IF(R24>=10,60,IF(R24>=0,45,IF(R24>=-10,30,15))))))),"")),"") | T24: 2 | U24: 3 | V24: 5 | W24: 5 | X24: 2 | Y24: =IFERROR((AVERAGE(T24,U24,V24,W24,X24)-1)*25,"") | Z24: 4 | AA24: 3 | AB24: 3 | AC24: 10 | AD24: =IFERROR(AVERAGE(IFERROR(IF(Z24="","",Z24*20),""),IFERROR(IF(AA24="","",AA24*20),""),IFERROR(IF(AB24="","",AB24*20),""),IFERROR(IF(AC24="","",IF(AC24>=85,100,IF(AC24>=70,90,IF(AC24>=55,75,IF(AC24>=40,60,IF(AC24>=25,40,20)))))),"")),"") | AE24: 4 | AF24: 5 | AG24: 4 | AH24: 4 | AI24: =IFERROR((AVERAGE(AE24,AF24,AG24,AH24,AL24)-1)*25,"") | AJ24: =IFERROR(J24*Weights!$B$4 + O24*Weights!$B$5 + S24*Weights!$B$6 + Y24*Weights!$B$7 + AD24*Weights!$B$8 + AI24*Weights!$B$9,"") | AK24: =IF(AJ24="","",IF(AJ24>=85,"✓✓✓",IF(AJ24>=70,"✓✓",IF(AJ24>=55,"✓",IF(AJ24>=40,"?","✗"))))) | AL24: 5
A25: SMR | B25: NuScale Power Corporation | C25: 01 Power Generation / Nuclear-specific | D25: 2026-10-11 | E25: -10.907438 | F25: -9.079 | G25: -26.36 | H25: 276.40826 | I25: =IF(OR(E25="",R25="",R25<=0,E25<0),"",E25/R25) | J25: 28.1 | K25: -28.65 | L25: 23.54 | M25: -7284.85 | O25: 11.6 | P25: 38.67 | Q25: -99.1 | S25: =IFERROR(AVERAGE(IFERROR(IF(P25="","",IF(P25>=40,100,IF(P25>=30,90,IF(P25>=20,75,IF(P25>=15,60,IF(P25>=10,45,IF(P25>=5,30,15))))))),""),IFERROR(IF(Q25="","",IF(Q25>=40,100,IF(Q25>=30,90,IF(Q25>=20,75,IF(Q25>=10,60,IF(Q25>=5,45,IF(Q25>=0,30,15))))))),""),IFERROR(IF(R25="","",IF(R25>=40,100,IF(R25>=30,90,IF(R25>=20,75,IF(R25>=10,60,IF(R25>=0,45,IF(R25>=-10,30,15))))))),"")),"") | T25: 1 | U25: 3 | V25: 3 | W25: 2 | X25: 2 | Y25: =IFERROR((AVERAGE(T25,U25,V25,W25,X25)-1)*25,"") | Z25: 1 | AA25: 1 | AB25: 1 | AC25: 34.2 | AD25: =IFERROR(AVERAGE(IFERROR(IF(Z25="","",Z25*20),""),IFERROR(IF(AA25="","",AA25*20),""),IFERROR(IF(AB25="","",AB25*20),""),IFERROR(IF(AC25="","",IF(AC25>=85,100,IF(AC25>=70,90,IF(AC25>=55,75,IF(AC25>=40,60,IF(AC25>=25,40,20)))))),"")),"") | AE25: 3 | AF25: 5 | AG25: 2 | AH25: 1 | AI25: =IFERROR((AVERAGE(AE25,AF25,AG25,AH25,AL25)-1)*25,"") | AJ25: =IFERROR(J25*Weights!$B$4 + O25*Weights!$B$5 + S25*Weights!$B$6 + Y25*Weights!$B$7 + AD25*Weights!$B$8 + AI25*Weights!$B$9,"") | AK25: =IF(AJ25="","",IF(AJ25>=85,"✓✓✓",IF(AJ25>=70,"✓✓",IF(AJ25>=55,"✓",IF(AJ25>=40,"?","✗"))))) | AL25: 5
A26: OKLO | B26: Oklo Inc. | C26: 01 Power Generation / Nuclear-specific | D26: 2026-10-11 | E26: -32.21464 | F26: -20.241 | G26: -4.27 | H26: 5334.556 | I26: =IF(OR(E26="",R26="",R26<=0,E26<0),"",E26/R26) | J26: 47.5 | K26: -5.21 | L26: 40.41 | M26: -22794.71 | O26: 12.1 | S26: =IFERROR(AVERAGE(IFERROR(IF(P26="","",IF(P26>=40,100,IF(P26>=30,90,IF(P26>=20,75,IF(P26>=15,60,IF(P26>=10,45,IF(P26>=5,30,15))))))),""),IFERROR(IF(Q26="","",IF(Q26>=40,100,IF(Q26>=30,90,IF(Q26>=20,75,IF(Q26>=10,60,IF(Q26>=5,45,IF(Q26>=0,30,15))))))),""),IFERROR(IF(R26="","",IF(R26>=40,100,IF(R26>=30,90,IF(R26>=20,75,IF(R26>=10,60,IF(R26>=0,45,IF(R26>=-10,30,15))))))),"")),"") | T26: 1 | U26: 3 | V26: 3 | W26: 5 | X26: 3 | Y26: =IFERROR((AVERAGE(T26,U26,V26,W26,X26)-1)*25,"") | Z26: 3 | AA26: 1 | AB26: 3 | AC26: 25 | AD26: =IFERROR(AVERAGE(IFERROR(IF(Z26="","",Z26*20),""),IFERROR(IF(AA26="","",AA26*20),""),IFERROR(IF(AB26="","",AB26*20),""),IFERROR(IF(AC26="","",IF(AC26>=85,100,IF(AC26>=70,90,IF(AC26>=55,75,IF(AC26>=40,60,IF(AC26>=25,40,20)))))),"")),"") | AE26: 3 | AF26: 5 | AG26: 3 | AH26: 4 | AI26: =IFERROR((AVERAGE(AE26,AF26,AG26,AH26,AL26)-1)*25,"") | AJ26: =IFERROR(J26*Weights!$B$4 + O26*Weights!$B$5 + S26*Weights!$B$6 + Y26*Weights!$B$7 + AD26*Weights!$B$8 + AI26*Weights!$B$9,"") | AK26: =IF(AJ26="","",IF(AJ26>=85,"✓✓✓",IF(AJ26>=70,"✓✓",IF(AJ26>=55,"✓",IF(AJ26>=40,"?","✗"))))) | AL26: 5
A27: NNE | B27: NANO Nuclear Energy Inc. | C27: 01 Power Generation / Nuclear-specific | D27: 2026-10-11 | E27: -15.225806 | F27: -5.449 | G27: -4.62 | H27: 3848.4482 | I27: =IF(OR(E27="",R27="",R27<=0,E27<0),"",E27/R27) | J27: 37.9 | K27: -6.66 | L27: 29.07 | M27: -17776.09 | O27: 9.1 | S27: =IFERROR(AVERAGE(IFERROR(IF(P27="","",IF(P27>=40,100,IF(P27>=30,90,IF(P27>=20,75,IF(P27>=15,60,IF(P27>=10,45,IF(P27>=5,30,15))))))),""),IFERROR(IF(Q27="","",IF(Q27>=40,100,IF(Q27>=30,90,IF(Q27>=20,75,IF(Q27>=10,60,IF(Q27>=5,45,IF(Q27>=0,30,15))))))),""),IFERROR(IF(R27="","",IF(R27>=40,100,IF(R27>=30,90,IF(R27>=20,75,IF(R27>=10,60,IF(R27>=0,45,IF(R27>=-10,30,15))))))),"")),"") | T27: 1 | U27: 3 | V27: 3 | W27: 4 | X27: 2 | Y27: =IFERROR((AVERAGE(T27,U27,V27,W27,X27)-1)*25,"") | Z27: 4 | AA27: 1 | AB27: 3 | AC27: 29.2 | AD27: =IFERROR(AVERAGE(IFERROR(IF(Z27="","",Z27*20),""),IFERROR(IF(AA27="","",AA27*20),""),IFERROR(IF(AB27="","",AB27*20),""),IFERROR(IF(AC27="","",IF(AC27>=85,100,IF(AC27>=70,90,IF(AC27>=55,75,IF(AC27>=40,60,IF(AC27>=25,40,20)))))),"")),"") | AE27: 3 | AF27: 5 | AG27: 3 | AH27: 4 | AI27: =IFERROR((AVERAGE(AE27,AF27,AG27,AH27,AL27)-1)*25,"") | AJ27: =IFERROR(J27*Weights!$B$4 + O27*Weights!$B$5 + S27*Weights!$B$6 + Y27*Weights!$B$7 + AD27*Weights!$B$8 + AI27*Weights!$B$9,"") | AK27: =IF(AJ27="","",IF(AJ27>=85,"✓✓✓",IF(AJ27>=70,"✓✓",IF(AJ27>=55,"✓",IF(AJ27>=40,"?","✗"))))) | AL27: 5
A28: EQT | B28: EQT Corporation | C28: 01 Power Generation / Natural gas E&P (powering gas turbines for data centers) | D28: 2026-10-11 | E28: 14.009398 | F28: 5.985 | G28: 11.37 | H28: 3.5556598 | I28: =IF(OR(E28="",R28="",R28<=0,E28<0),"",E28/R28) | J28: 78.2 | K28: 7.96 | L28: 80.75 | M28: 40.44 | N28: 0.79 | O28: 91.8 | P28: -11.72 | Q28: -3.9 | R28: -73 | S28: =IFERROR(AVERAGE(IFERROR(IF(P28="","",IF(P28>=40,100,IF(P28>=30,90,IF(P28>=20,75,IF(P28>=15,60,IF(P28>=10,45,IF(P28>=5,30,15))))))),""),IFERROR(IF(Q28="","",IF(Q28>=40,100,IF(Q28>=30,90,IF(Q28>=20,75,IF(Q28>=10,60,IF(Q28>=5,45,IF(Q28>=0,30,15))))))),""),IFERROR(IF(R28="","",IF(R28>=40,100,IF(R28>=30,90,IF(R28>=20,75,IF(R28>=10,60,IF(R28>=0,45,IF(R28>=-10,30,15))))))),"")),"") | T28: 1 | U28: 2 | V28: 3 | W28: 5 | X28: 2 | Y28: =IFERROR((AVERAGE(T28,U28,V28,W28,X28)-1)*25,"") | Z28: 2 | AA28: 1 | AB28: 3 | AC28: 29.2 | AD28: =IFERROR(AVERAGE(IFERROR(IF(Z28="","",Z28*20),""),IFERROR(IF(AA28="","",AA28*20),""),IFERROR(IF(AB28="","",AB28*20),""),IFERROR(IF(AC28="","",IF(AC28>=85,100,IF(AC28>=70,90,IF(AC28>=55,75,IF(AC28>=40,60,IF(AC28>=25,40,20)))))),"")),"") | AE28: 4 | AF28: 5 | AG28: 5 | AH28: 4 | AI28: =IFERROR((AVERAGE(AE28,AF28,AG28,AH28,AL28)-1)*25,"") | AJ28: =IFERROR(J28*Weights!$B$4 + O28*Weights!$B$5 + S28*Weights!$B$6 + Y28*Weights!$B$7 + AD28*Weights!$B$8 + AI28*Weights!$B$9,"") | AK28: =IF(AJ28="","",IF(AJ28>=85,"✓✓✓",IF(AJ28>=70,"✓✓",IF(AJ28>=55,"✓",IF(AJ28>=40,"?","✗"))))) | AL28: 5
A29: RRC | B29: Range Resources Corporation | C29: 01 Power Generation / Natural gas E&P (powering gas turbines for data centers) | D29: 2026-10-11 | E29: 10.368882 | F29: 6.356 | G29: 7.22 | H29: 2.921856 | I29: =IF(OR(E29="",R29="",R29<=0,E29<0),"",E29/R29) | J29: 77.9 | K29: 12.19 | L29: 52.12 | M29: 21.1 | N29: 0.63 | O29: 88.6 | P29: -17.55 | Q29: 8.6 | R29: -17.8 | S29: =IFERROR(AVERAGE(IFERROR(IF(P29="","",IF(P29>=40,100,IF(P29>=30,90,IF(P29>=20,75,IF(P29>=15,60,IF(P29>=10,45,IF(P29>=5,30,15))))))),""),IFERROR(IF(Q29="","",IF(Q29>=40,100,IF(Q29>=30,90,IF(Q29>=20,75,IF(Q29>=10,60,IF(Q29>=5,45,IF(Q29>=0,30,15))))))),""),IFERROR(IF(R29="","",IF(R29>=40,100,IF(R29>=30,90,IF(R29>=20,75,IF(R29>=10,60,IF(R29>=0,45,IF(R29>=-10,30,15))))))),"")),"") | T29: 1 | U29: 2 | V29: 2 | W29: 4 | X29: 1 | Y29: =IFERROR((AVERAGE(T29,U29,V29,W29,X29)-1)*25,"") | Z29: 4 | AA29: 1 | AB29: 3 | AC29: 40.8 | AD29: =IFERROR(AVERAGE(IFERROR(IF(Z29="","",Z29*20),""),IFERROR(IF(AA29="","",AA29*20),""),IFERROR(IF(AB29="","",AB29*20),""),IFERROR(IF(AC29="","",IF(AC29>=85,100,IF(AC29>=70,90,IF(AC29>=55,75,IF(AC29>=40,60,IF(AC29>=25,40,20)))))),"")),"") | AE29: 4 | AF29: 5 | AG29: 5 | AH29: 4 | AI29: =IFERROR((AVERAGE(AE29,AF29,AG29,AH29,AL29)-1)*25,"") | AJ29: =IFERROR(J29*Weights!$B$4 + O29*Weights!$B$5 + S29*Weights!$B$6 + Y29*Weights!$B$7 + AD29*Weights!$B$8 + AI29*Weights!$B$9,"") | AK29: =IF(AJ29="","",IF(AJ29>=85,"✓✓✓",IF(AJ29>=70,"✓✓",IF(AJ29>=55,"✓",IF(AJ29>=40,"?","✗"))))) | AL29: 5
A30: AR | B30: Antero Resources Corporation | C30: 01 Power Generation / Natural gas E&P (powering gas turbines for data centers) | D30: 2026-10-11 | E30: 8.182038 | G30: 14.45 | H30: 1.9091189 | I30: =IF(OR(E30="",R30="",R30<=0,E30<0),"",E30/R30) | J30: 86.8 | K30: 6.71 | L30: 67.15 | M30: 27.58 | O30: 86.3 | P30: -15.47 | Q30: 12.6 | R30: 78 | S30: =IFERROR(AVERAGE(IFERROR(IF(P30="","",IF(P30>=40,100,IF(P30>=30,90,IF(P30>=20,75,IF(P30>=15,60,IF(P30>=10,45,IF(P30>=5,30,15))))))),""),IFERROR(IF(Q30="","",IF(Q30>=40,100,IF(Q30>=30,90,IF(Q30>=20,75,IF(Q30>=10,60,IF(Q30>=5,45,IF(Q30>=0,30,15))))))),""),IFERROR(IF(R30="","",IF(R30>=40,100,IF(R30>=30,90,IF(R30>=20,75,IF(R30>=10,60,IF(R30>=0,45,IF(R30>=-10,30,15))))))),"")),"") | T30: 1 | U30: 2 | V30: 2 | W30: 5 | X30: 1 | Y30: =IFERROR((AVERAGE(T30,U30,V30,W30,X30)-1)*25,"") | Z30: 5 | AA30: 1 | AB30: 3 | AC30: 30.8 | AD30: =IFERROR(AVERAGE(IFERROR(IF(Z30="","",Z30*20),""),IFERROR(IF(AA30="","",AA30*20),""),IFERROR(IF(AB30="","",AB30*20),""),IFERROR(IF(AC30="","",IF(AC30>=85,100,IF(AC30>=70,90,IF(AC30>=55,75,IF(AC30>=40,60,IF(AC30>=25,40,20)))))),"")),"") | AE30: 4 | AF30: 5 | AG30: 4 | AH30: 4 | AI30: =IFERROR((AVERAGE(AE30,AF30,AG30,AH30,AL30)-1)*25,"") | AJ30: =IFERROR(J30*Weights!$B$4 + O30*Weights!$B$5 + S30*Weights!$B$6 + Y30*Weights!$B$7 + AD30*Weights!$B$8 + AI30*Weights!$B$9,"") | AK30: =IF(AJ30="","",IF(AJ30>=85,"✓✓✓",IF(AJ30>=70,"✓✓",IF(AJ30>=55,"✓",IF(AJ30>=40,"?","✗"))))) | AL30: 5
A31: EXE | B31: Expand Energy Corporation | C31: 01 Power Generation / Natural gas E&P (powering gas turbines for data centers) | D31: 2026-10-11 | E31: 10.623668 | F31: 3.491 | G31: 11.74 | H31: 1.6673068 | I31: =IF(OR(E31="",R31="",R31<=0,E31<0),"",E31/R31) | J31: 82.8 | K31: 12.56 | L31: 47.07 | M31: 19.57 | N31: 0.46 | O31: 86.2 | P31: 2.13 | Q31: -10.6 | S31: =IFERROR(AVERAGE(IFERROR(IF(P31="","",IF(P31>=40,100,IF(P31>=30,90,IF(P31>=20,75,IF(P31>=15,60,IF(P31>=10,45,IF(P31>=5,30,15))))))),""),IFERROR(IF(Q31="","",IF(Q31>=40,100,IF(Q31>=30,90,IF(Q31>=20,75,IF(Q31>=10,60,IF(Q31>=5,45,IF(Q31>=0,30,15))))))),""),IFERROR(IF(R31="","",IF(R31>=40,100,IF(R31>=30,90,IF(R31>=20,75,IF(R31>=10,60,IF(R31>=0,45,IF(R31>=-10,30,15))))))),"")),"") | T31: 1 | U31: 2 | V31: 2 | W31: 5 | X31: 1 | Y31: =IFERROR((AVERAGE(T31,U31,V31,W31,X31)-1)*25,"") | Z31: 5 | AA31: 1 | AB31: 3 | AC31: 30.8 | AD31: =IFERROR(AVERAGE(IFERROR(IF(Z31="","",Z31*20),""),IFERROR(IF(AA31="","",AA31*20),""),IFERROR(IF(AB31="","",AB31*20),""),IFERROR(IF(AC31="","",IF(AC31>=85,100,IF(AC31>=70,90,IF(AC31>=55,75,IF(AC31>=40,60,IF(AC31>=25,40,20)))))),"")),"") | AE31: 4 | AF31: 5 | AG31: 5 | AH31: 4 | AI31: =IFERROR((AVERAGE(AE31,AF31,AG31,AH31,AL31)-1)*25,"") | AJ31: =IFERROR(J31*Weights!$B$4 + O31*Weights!$B$5 + S31*Weights!$B$6 + Y31*Weights!$B$7 + AD31*Weights!$B$8 + AI31*Weights!$B$9,"") | AK31: =IF(AJ31="","",IF(AJ31>=85,"✓✓✓",IF(AJ31>=70,"✓✓",IF(AJ31>=55,"✓",IF(AJ31>=40,"?","✗"))))) | AL31: 5
A32: PLUG | B32: Plug Power Inc. | C32: 01 Power Generation / Distributed / on-site power | D32: 2026-10-11 | E32: -11.326097 | F32: -6.556 | G32: -23.88 | H32: 3.1545882 | I32: =IF(OR(E32="",R32="",R32<=0,E32<0),"",E32/R32) | J32: 31.6 | K32: -23.36 | L32: -24.75 | M32: -75.33 | O32: 4.7 | P32: 0.4 | Q32: 2.5 | S32: =IFERROR(AVERAGE(IFERROR(IF(P32="","",IF(P32>=40,100,IF(P32>=30,90,IF(P32>=20,75,IF(P32>=15,60,IF(P32>=10,45,IF(P32>=5,30,15))))))),""),IFERROR(IF(Q32="","",IF(Q32>=40,100,IF(Q32>=30,90,IF(Q32>=20,75,IF(Q32>=10,60,IF(Q32>=5,45,IF(Q32>=0,30,15))))))),""),IFERROR(IF(R32="","",IF(R32>=40,100,IF(R32>=30,90,IF(R32>=20,75,IF(R32>=10,60,IF(R32>=0,45,IF(R32>=-10,30,15))))))),"")),"") | T32: 1 | U32: 2 | V32: 2 | W32: 3 | X32: 2 | Y32: =IFERROR((AVERAGE(T32,U32,V32,W32,X32)-1)*25,"") | Z32: 3 | AA32: 5 | AB32: 3 | AC32: 28.3 | AD32: =IFERROR(AVERAGE(IFERROR(IF(Z32="","",Z32*20),""),IFERROR(IF(AA32="","",AA32*20),""),IFERROR(IF(AB32="","",AB32*20),""),IFERROR(IF(AC32="","",IF(AC32>=85,100,IF(AC32>=70,90,IF(AC32>=55,75,IF(AC32>=40,60,IF(AC32>=25,40,20)))))),"")),"") | AE32: 3 | AF32: 4 | AG32: 2 | AH32: 4 | AI32: =IFERROR((AVERAGE(AE32,AF32,AG32,AH32,AL32)-1)*25,"") | AJ32: =IFERROR(J32*Weights!$B$4 + O32*Weights!$B$5 + S32*Weights!$B$6 + Y32*Weights!$B$7 + AD32*Weights!$B$8 + AI32*Weights!$B$9,"") | AK32: =IF(AJ32="","",IF(AJ32>=85,"✓✓✓",IF(AJ32>=70,"✓✓",IF(AJ32>=55,"✓",IF(AJ32>=40,"?","✗"))))) | AL32: 5
A33: CMI | B33: Cummins Inc. | C33: 01 Power Generation / Distributed / on-site power | D33: 2026-10-11 | E33: 15.038128 | F33: 15.266 | G33: 3.7 | H33: 2.080849 | I33: =IF(OR(E33="",R33="",R33<=0,E33<0),"",E33/R33) | J33: 57.6 | K33: 11.7 | L33: 25.77 | M33: 7.7 | N33: 0.87 | O33: 67.1 | P33: 6.25 | Q33: 9.4 | R33: 4.7 | S33: =IFERROR(AVERAGE(IFERROR(IF(P33="","",IF(P33>=40,100,IF(P33>=30,90,IF(P33>=20,75,IF(P33>=15,60,IF(P33>=10,45,IF(P33>=5,30,15))))))),""),IFERROR(IF(Q33="","",IF(Q33>=40,100,IF(Q33>=30,90,IF(Q33>=20,75,IF(Q33>=10,60,IF(Q33>=5,45,IF(Q33>=0,30,15))))))),""),IFERROR(IF(R33="","",IF(R33>=40,100,IF(R33>=30,90,IF(R33>=20,75,IF(R33>=10,60,IF(R33>=0,45,IF(R33>=-10,30,15))))))),"")),"") | T33: 2 | U33: 4 | V33: 4 | W33: 5 | X33: 2 | Y33: =IFERROR((AVERAGE(T33,U33,V33,W33,X33)-1)*25,"") | Z33: 5 | AA33: 5 | AB33: 3 | AC33: 41.7 | AD33: =IFERROR(AVERAGE(IFERROR(IF(Z33="","",Z33*20),""),IFERROR(IF(AA33="","",AA33*20),""),IFERROR(IF(AB33="","",AB33*20),""),IFERROR(IF(AC33="","",IF(AC33>=85,100,IF(AC33>=70,90,IF(AC33>=55,75,IF(AC33>=40,60,IF(AC33>=25,40,20)))))),"")),"") | AE33: 5 | AF33: 4 | AG33: 4 | AH33: 4 | AI33: =IFERROR((AVERAGE(AE33,AF33,AG33,AH33,AL33)-1)*25,"") | AJ33: =IFERROR(J33*Weights!$B$4 + O33*Weights!$B$5 + S33*Weights!$B$6 + Y33*Weights!$B$7 + AD33*Weights!$B$8 + AI33*Weights!$B$9,"") | AK33: =IF(AJ33="","",IF(AJ33>=85,"✓✓✓",IF(AJ33>=70,"✓✓",IF(AJ33>=55,"✓",IF(AJ33>=40,"?","✗"))))) | AL33: 5
A34: GNRC | B34: Generac Holdings Inc. | C34: 01 Power Generation / Distributed / on-site power | D34: 2026-10-11 | E34: 17.343113 | F34: 22.318 | G34: 2.85 | H34: 2.9931617 | I34: =IF(OR(E34="",R34="",R34<=0,E34<0),"",E34/R34) | J34: 57.9 | K34: 7.06 | L34: 39.54 | M34: 8.54 | N34: 1.79 | O34: 61 | P34: -2.67 | Q34: 10.6 | R34: 93.5 | S34: =IFERROR(AVERAGE(IFERROR(IF(P34="","",IF(P34>=40,100,IF(P34>=30,90,IF(P34>=20,75,IF(P34>=15,60,IF(P34>=10,45,IF(P34>=5,30,15))))))),""),IFERROR(IF(Q34="","",IF(Q34>=40,100,IF(Q34>=30,90,IF(Q34>=20,75,IF(Q34>=10,60,IF(Q34>=5,45,IF(Q34>=0,30,15))))))),""),IFERROR(IF(R34="","",IF(R34>=40,100,IF(R34>=30,90,IF(R34>=20,75,IF(R34>=10,60,IF(R34>=0,45,IF(R34>=-10,30,15))))))),"")),"") | T34: 2 | U34: 3 | V34: 3 | W34: 5 | X34: 3 | Y34: =IFERROR((AVERAGE(T34,U34,V34,W34,X34)-1)*25,"") | Z34: 5 | AA34: 5 | AB34: 3 | AC34: 53.3 | AD34: =IFERROR(AVERAGE(IFERROR(IF(Z34="","",Z34*20),""),IFERROR(IF(AA34="","",AA34*20),""),IFERROR(IF(AB34="","",AB34*20),""),IFERROR(IF(AC34="","",IF(AC34>=85,100,IF(AC34>=70,90,IF(AC34>=55,75,IF(AC34>=40,60,IF(AC34>=25,40,20)))))),"")),"") | AE34: 4 | AF34: 4 | AG34: 4 | AH34: 4 | AI34: =IFERROR((AVERAGE(AE34,AF34,AG34,AH34,AL34)-1)*25,"") | AJ34: =IFERROR(J34*Weights!$B$4 + O34*Weights!$B$5 + S34*Weights!$B$6 + Y34*Weights!$B$7 + AD34*Weights!$B$8 + AI34*Weights!$B$9,"") | AK34: =IF(AJ34="","",IF(AJ34>=85,"✓✓✓",IF(AJ34>=70,"✓✓",IF(AJ34>=55,"✓",IF(AJ34>=40,"?","✗"))))) | AL34: 5
A35: ETN | B35: Eaton Corporation plc | C35: 02 Grid & Power Equipment | D35: 2026-10-11 | E35: 26.446348 | F35: 28.348 | G35: 2.26 | H35: 5.556288 | I35: =IF(OR(E35="",R35="",R35<=0,E35<0),"",E35/R35) | J35: 33.4 | K35: 9.82 | L35: 36.02 | M35: 12.58 | N35: 3.11 | O35: 55.6 | P35: 9.77 | Q35: 21.4 | R35: -16.4 | S35: =IFERROR(AVERAGE(IFERROR(IF(P35="","",IF(P35>=40,100,IF(P35>=30,90,IF(P35>=20,75,IF(P35>=15,60,IF(P35>=10,45,IF(P35>=5,30,15))))))),""),IFERROR(IF(Q35="","",IF(Q35>=40,100,IF(Q35>=30,90,IF(Q35>=20,75,IF(Q35>=10,60,IF(Q35>=5,45,IF(Q35>=0,30,15))))))),""),IFERROR(IF(R35="","",IF(R35>=40,100,IF(R35>=30,90,IF(R35>=20,75,IF(R35>=10,60,IF(R35>=0,45,IF(R35>=-10,30,15))))))),"")),"") | T35: 4 | U35: 4 | V35: 4 | W35: 5 | X35: 5 | Y35: =IFERROR((AVERAGE(T35,U35,V35,W35,X35)-1)*25,"") | Z35: 5 | AA35: 3 | AB35: 3 | AC35: 67.5 | AD35: =IFERROR(AVERAGE(IFERROR(IF(Z35="","",Z35*20),""),IFERROR(IF(AA35="","",AA35*20),""),IFERROR(IF(AB35="","",AB35*20),""),IFERROR(IF(AC35="","",IF(AC35>=85,100,IF(AC35>=70,90,IF(AC35>=55,75,IF(AC35>=40,60,IF(AC35>=25,40,20)))))),"")),"") | AE35: 5 | AF35: 4 | AG35: 4 | AH35: 4 | AI35: =IFERROR((AVERAGE(AE35,AF35,AG35,AH35,AL35)-1)*25,"") | AJ35: =IFERROR(J35*Weights!$B$4 + O35*Weights!$B$5 + S35*Weights!$B$6 + Y35*Weights!$B$7 + AD35*Weights!$B$8 + AI35*Weights!$B$9,"") | AK35: =IF(AJ35="","",IF(AJ35>=85,"✓✓✓",IF(AJ35>=70,"✓✓",IF(AJ35>=55,"✓",IF(AJ35>=40,"?","✗"))))) | AL35: 5
A36: SBGSY | B36: Schneider Electric S.E. | C36: 02 Grid & Power Equipment | D36: 2026-10-11 | E36: 21.28942 | F36: 19.52 | G36: 3.58 | H36: 3.57 | I36: =IF(OR(E36="",R36="",R36<=0,E36<0),"",E36/R36) | J36: 69.8 | K36: 12.2 | L36: 42.12 | M36: 12.78 | N36: 1.91 | O36: 79 | P36: 5.52 | Q36: 9.8 | R36: 30.1 | S36: =IFERROR(AVERAGE(IFERROR(IF(P36="","",IF(P36>=40,100,IF(P36>=30,90,IF(P36>=20,75,IF(P36>=15,60,IF(P36>=10,45,IF(P36>=5,30,15))))))),""),IFERROR(IF(Q36="","",IF(Q36>=40,100,IF(Q36>=30,90,IF(Q36>=20,75,IF(Q36>=10,60,IF(Q36>=5,45,IF(Q36>=0,30,15))))))),""),IFERROR(IF(R36="","",IF(R36>=40,100,IF(R36>=30,90,IF(R36>=20,75,IF(R36>=10,60,IF(R36>=0,45,IF(R36>=-10,30,15))))))),"")),"") | T36: 4 | U36: 4 | V36: 4 | W36: 5 | X36: 4 | Y36: =IFERROR((AVERAGE(T36,U36,V36,W36,X36)-1)*25,"") | Z36: 4 | AA36: 4 | AB36: 3 | AC36: 68.3 | AD36: =IFERROR(AVERAGE(IFERROR(IF(Z36="","",Z36*20),""),IFERROR(IF(AA36="","",AA36*20),""),IFERROR(IF(AB36="","",AB36*20),""),IFERROR(IF(AC36="","",IF(AC36>=85,100,IF(AC36>=70,90,IF(AC36>=55,75,IF(AC36>=40,60,IF(AC36>=25,40,20)))))),"")),"") | AE36: 5 | AF36: 4 | AG36: 3 | AH36: 4 | AI36: =IFERROR((AVERAGE(AE36,AF36,AG36,AH36,AL36)-1)*25,"") | AJ36: =IFERROR(J36*Weights!$B$4 + O36*Weights!$B$5 + S36*Weights!$B$6 + Y36*Weights!$B$7 + AD36*Weights!$B$8 + AI36*Weights!$B$9,"") | AK36: =IF(AJ36="","",IF(AJ36>=85,"✓✓✓",IF(AJ36>=70,"✓✓",IF(AJ36>=55,"✓",IF(AJ36>=40,"?","✗"))))) | AL36: 5
A37: ABBNY | B37: ABB Ltd | C37: 02 Grid & Power Equipment | D37: 2026-10-11 | E37: 26.253393 | F37: 98.238 | G37: 2.39 | H37: 4.857817 | I37: =IF(OR(E37="",R37="",R37<=0,E37<0),"",E37/R37) | J37: 32.2 | K37: 16.73 | L37: 40.25 | M37: 11.63 | N37: 0.46 | O37: 78.2 | P37: 4.1 | Q37: 14.2 | R37: 7 | S37: =IFERROR(AVERAGE(IFERROR(IF(P37="","",IF(P37>=40,100,IF(P37>=30,90,IF(P37>=20,75,IF(P37>=15,60,IF(P37>=10,45,IF(P37>=5,30,15))))))),""),IFERROR(IF(Q37="","",IF(Q37>=40,100,IF(Q37>=30,90,IF(Q37>=20,75,IF(Q37>=10,60,IF(Q37>=5,45,IF(Q37>=0,30,15))))))),""),IFERROR(IF(R37="","",IF(R37>=40,100,IF(R37>=30,90,IF(R37>=20,75,IF(R37>=10,60,IF(R37>=0,45,IF(R37>=-10,30,15))))))),"")),"") | T37: 4 | U37: 4 | V37: 4 | W37: 5 | X37: 4 | Y37: =IFERROR((AVERAGE(T37,U37,V37,W37,X37)-1)*25,"") | Z37: 5 | AA37: 5 | AB37: 3 | AC37: 50 | AD37: =IFERROR(AVERAGE(IFERROR(IF(Z37="","",Z37*20),""),IFERROR(IF(AA37="","",AA37*20),""),IFERROR(IF(AB37="","",AB37*20),""),IFERROR(IF(AC37="","",IF(AC37>=85,100,IF(AC37>=70,90,IF(AC37>=55,75,IF(AC37>=40,60,IF(AC37>=25,40,20)))))),"")),"") | AE37: 5 | AF37: 4 | AG37: 4 | AH37: 4 | AI37: =IFERROR((AVERAGE(AE37,AF37,AG37,AH37,AL37)-1)*25,"") | AJ37: =IFERROR(J37*Weights!$B$4 + O37*Weights!$B$5 + S37*Weights!$B$6 + Y37*Weights!$B$7 + AD37*Weights!$B$8 + AI37*Weights!$B$9,"") | AK37: =IF(AJ37="","",IF(AJ37>=85,"✓✓✓",IF(AJ37>=70,"✓✓",IF(AJ37>=55,"✓",IF(AJ37>=40,"?","✗"))))) | AL37: 5
