Workbook

Sheet Summary
A1: Field | B1: Value | C1: Source / formula
A2: Ticker | B2: 5347.TWO | C2: input
A3: Name | B3: Vanguard International Semiconductor Corporation | C3: yfinance info.longName
A4: Sector | B4: Technology | C4: yfinance info.sector
A5: Industry | B5: Semiconductors | C5: yfinance info.industry
A6: Market cap ($) | B6: 371911229440 | C6: yfinance info.marketCap
A7: Enterprise value ($) | B7: 408145166336 | C7: yfinance info.enterpriseValue
A8: Trailing P/E | B8: 47.03088 | C8: yfinance info.trailingPE
A9: Forward P/E | B9: 31.877539 | C9: yfinance info.forwardPE
A10: P/S (TTM) | B10: 7.563238 | C10: yfinance
A11: Gross margin (TTM) | B11: 0.27917 | C11: yfinance info.grossMargins
A12: Operating margin (TTM) | B12: 0.1665 | C12: yfinance info.operatingMargins
A13: Net margin (TTM) | B13: 0.1574 | C13: yfinance info.profitMargins
A14: ROE | B14: 0.090270005 | C14: yfinance info.returnOnEquity
A15: Revenue growth (YoY) | B15: 0.049 | C15: yfinance info.revenueGrowth
A16: Total cash ($) | B16: 42086531072 | C16: yfinance info.totalCash
A17: Total debt ($) | B17: 42051837952 | C17: yfinance info.totalDebt
... A20: Current price ($) | B20: 198 | C20: yfinance info.currentPrice
A21: FCF yield | B21: =IFERROR(B18/B6,"") | C21: =B18/B6
A22: FCF / EV | B22: =IFERROR(B18/B7,"") | C22: =B18/B7

Sheet FY Summary
A1: Fiscal-year summary (GAAP, $ except where noted) | B1: FY-3 | C1: FY-2 | D1: FY-1 | E1: TTM | F1: Source / formula
A2: Fiscal period end | B2: 2023-12-31 | C2: 2024-12-31 | D2: 2025-12-31 | E2: TTM → 2025-12-31 | F2: annual statement headers; TTM = Σ last 4 quarters
A3: Revenue | B3: ='Income stmt (annual)'!D45 | C3: ='Income stmt (annual)'!C45 | D3: ='Income stmt (annual)'!B45 | E3: =SUM('Income stmt (quarterly)'!B44:E44) | F3: Total Revenue
A4: Gross profit | B4: ='Income stmt (annual)'!D43 | C4: ='Income stmt (annual)'!C43 | D4: ='Income stmt (annual)'!B43 | E4: =SUM('Income stmt (quarterly)'!B42:E42) | F4: Gross Profit (GAAP)
A5: Gross margin % | B5: =IFERROR(B4/B3,"") | C5: =IFERROR(C4/C3,"") | D5: =IFERROR(D4/D3,"") | E5: =IFERROR(E4/E3,"") | F5: GAAP = gross profit / revenue
A6: Operating income | B6: ='Income stmt (annual)'!D37 | C6: ='Income stmt (annual)'!C37 | D6: ='Income stmt (annual)'!B37 | E6: =SUM('Income stmt (quarterly)'!B36:E36) | F6: Operating Income
A7: Operating margin % | B7: =IFERROR(B6/B3,"") | C7: =IFERROR(C6/C3,"") | D7: =IFERROR(D6/D3,"") | E7: =IFERROR(E6/E3,"") | F7: =operating income / revenue
A8: EBITDA | B8: ='Income stmt (annual)'!D10 | C8: ='Income stmt (annual)'!C10 | D8: ='Income stmt (annual)'!B10 | E8: =SUM('Income stmt (quarterly)'!B10:E10) | F8: EBITDA
A9: Free cash flow | B9: ='Cash flow (annual)'!D2 | C9: ='Cash flow (annual)'!C2 | D9: ='Cash flow (annual)'!B2 | E9: =SUM('Cash flow (quarterly)'!B2:E2) | F9: FCF = OCF − capex
A10: FCF margin % | B10: =IFERROR(B9/B3,"") | C10: =IFERROR(C9/C3,"") | D10: =IFERROR(D9/D3,"") | E10: =IFERROR(E9/E3,"") | F10: =FCF / revenue
A11: Capex | B11: =-'Cash flow (annual)'!D6 | C11: =-'Cash flow (annual)'!C6 | D11: =-'Cash flow (annual)'!B6 | E11: =-SUM('Cash flow (quarterly)'!B4:E4) | F11: Capex (shown positive)
A12: Capex / revenue % | B12: =IFERROR(B11/B3,"") | C12: =IFERROR(C11/C3,"") | D12: =IFERROR(D11/D3,"") | E12: =IFERROR(E11/E3,"") | F12: =capex / revenue
A13: Net debt | F13: Net debt; TTM = MRQ
A14: Net debt / EBITDA | B14: =IFERROR(B13/B8,"") | C14: =IFERROR(C13/C8,"") | D14: =IFERROR(D13/D8,"") | E14: =IFERROR(E13/E8,"") | F14: =net debt / EBITDA
A15: Share count (period-end, M) | B15: ='Balance sheet (annual)'!D3/1e6 | C15: ='Balance sheet (annual)'!C3/1e6 | D15: ='Balance sheet (annual)'!B3/1e6 | E15: ='Balance sheet (quarterly)'!B2/1e6 | F15: shares ÷ 1e6; TTM = MRQ
A16: Share count YoY % | C16: =IFERROR(C15/B15-1,"") | D16: =IFERROR(D15/C15-1,"") | E16: =IFERROR(E15/D15-1,"") | F16: vs prior period

Sheet Income stmt (annual)
A1: Line item | B1: 2025-12-31 | C1: 2024-12-31 | D1: 2023-12-31 | E1: 2022-12-31
A2: Tax Effect Of Unusual Items | B2: 33473057 | C2: 2733865.7 | D2: 2.5615374e+08 | E2: 32692520
A3: Tax Rate For Calcs | B3: 0.160019 | C3: 0.194817 | D3: 0.165694 | E3: 0.18942
A4: Normalized EBITDA | B4: 17933846000 | C4: 17708406000 | D4: 15378086000 | E4: 24400767000
A5: Total Unusual Items | B5: 209182000 | C5: 14033000 | D5: 1545949000 | E5: 172593000
A6: Total Unusual Items Excluding Goodwill | B6: 209182000 | C6: 14033000 | D6: 1545949000 | E6: 172593000
A7: Net Income From Continuing Operation Net Minority Interest | B7: 7907502000 | C7: 7046424000 | D7: 7370074000 | E7: 15280388000
A8: Reconciled Depreciation | B8: 8552173000 | C8: 8622021000 | D8: 7852088000 | E8: 5542087000
A9: Reconciled Cost Of Revenue | B9: 34937406000 | C9: 32121848000 | D9: 27826556000 | E9: 27770570000
A10: EBITDA | B10: 18143028000 | C10: 17722439000 | D10: 16924035000 | E10: 24573360000
A11: EBIT | B11: 9590855000 | C11: 9100418000 | D11: 9071947000 | E11: 19031273000
A12: Net Interest Income | B12: 1484498000 | C12: 1665264000 | D12: 1445197000 | E12: 499673000
A13: Interest Expense | B13: 340112000 | C13: 348113000 | D13: 238174000 | E13: 180101000
... A46: Operating Revenue | B46: 48591245000 | C46: 44054762000 | D46: 38272570000 | E46: 51694310000

Sheet Income stmt (quarterly)
A1: Line item | B1: 2025-12-31 | C1: 2025-06-30 | D1: 2025-03-31 | E1: 2024-12-31
A2: Tax Effect Of Unusual Items | B2: -10470452 | C2: 48659280 | D2: -4715908.8 | E2: -7039938.4
A3: Tax Rate For Calcs | B3: 0.204621 | C3: 0.154984 | D3: 0.100465 | E3: 0.20969
A4: Normalized EBITDA | B4: 4448601000 | C4: 4237778000 | D4: 4852705000 | E4: 4709965000
A5: Total Unusual Items | B5: -51170000 | C5: 313964000 | D5: -46941000 | E5: -33573000
A6: Total Unusual Items Excluding Goodwill | B6: -51170000 | C6: 313964000 | D6: -46941000 | E6: -33573000
A7: Net Income From Continuing Operation Net Minority Interest | B7: 1747504000 | C7: 2043020000 | D7: 2413826000 | E7: 1846652000
A8: Reconciled Depreciation | B8: 2215742000 | C8: 2085966000 | D8: 2045795000 | E8: 2255191000
A9: Reconciled Cost Of Revenue | B9: 9129202000 | C9: 8419019000 | D9: 8352408000 | E9: 8238899000
A10: EBITDA | B10: 4397431000 | C10: 4551742000 | D10: 4805764000 | E10: 4676392000
A11: EBIT | B11: 2181689000 | C11: 2465776000 | D11: 2759969000 | E11: 2421201000
A12: Net Interest Income | B12: 313503000 | C12: 390598000 | D12: 473436000 | E12: 464330000
A13: Interest Expense | B13: 86600000 | C13: 84047000 | D13: 85196000 | E13: 88210000
... A17: Total Expenses | B17: 10787058000 | C17: 9802650000 | D17: 9711211000 | E17: 9627473000
A18: Diluted Average Shares | C18: 1857290909 | D18: 1856911000
A19: Basic Average Shares | C19: 1840558559 | D19: 1838982000
A20: Diluted EPS | C20: 1.1 | D20: 1.3
A21: Basic EPS | C21: 1.11 | D21: 1.31
A22: Diluted NI Availto Com Stockholders | B22: 1747504000 | C22: 2043020000 | D22: 2413826000 | E22: 1846652000
A23: Net Income Common Stockholders | B23: 1747504000 | C23: 2043020000 | D23: 2413826000 | E23: 1846652000
A24: Otherunder Preferred Stock Dividend | B24: 0 | C24: 0 | D24: 0 | E24: 0
A25: Net Income | B25: 1747504000 | C25: 2043020000 | D25: 2413826000 | E25: 1846652000
A26: Minority Interests | B26: 81114000 | C26: 30420000 | D26: 7773000 | E26: 2867000
A27: Net Income Including Noncontrolling Interests | B27: 1666390000 | C27: 2012600000 | D27: 2406053000 | E27: 1843785000
A28: Net Income Continuous Operations | B28: 1666390000 | C28: 2012600000 | D28: 2406053000 | E28: 1843785000
A29: Tax Provision | B29: 428699000 | C29: 369129000 | D29: 268720000 | E29: 489206000
A30: Pretax Income | B30: 2095089000 | C30: 2381729000 | D30: 2674773000 | E30: 2332991000
A31: Other Non Operating Income Expenses | B31: 16116000 | C31: 2515000 | D31: 3207000 | E31: 7450000
A32: Special Income Charges | E32: 867000
A33: Net Non Operating Interest Income Expense | B33: 313503000 | C33: 390598000 | D33: 473436000 | E33: 464330000
A34: Interest Expense Non Operating | B34: 86600000 | C34: 84047000 | D34: 85196000 | E34: 88210000
A35: Interest Income Non Operating | B35: 400103000 | C35: 474645000 | D35: 558632000 | E35: 552540000
A36: Operating Income | B36: 1806669000 | C36: 1896671000 | D36: 2238120000 | E36: 1925201000
A37: Operating Expense | B37: 1657856000 | C37: 1383631000 | D37: 1358803000 | E37: 1388574000
A38: Research And Development | B38: 582363000 | C38: 522169000 | D38: 520574000 | E38: 583314000
A39: Selling General And Administration | B39: 1075493000 | C39: 861462000 | D39: 838229000 | E39: 805260000
A40: Selling And Marketing Expense | B40: 163451000 | C40: 120165000 | D40: 129421000 | E40: 124726000
A41: General And Administrative Expense | B41: 912042000 | C41: 741297000 | D41: 708808000 | E41: 680534000
A42: Gross Profit | B42: 3464525000 | C42: 3280302000 | D42: 3596923000 | E42: 3313775000
A43: Cost Of Revenue | B43: 9129202000 | C43: 8419019000 | D43: 8352408000 | E43: 8238899000
...

Sheet Balance sheet (annual)
A1: Line item | B1: 2025-12-31 | C1: 2024-12-31 | D1: 2023-12-31 | E1: 2022-12-31 | F1: 2021-12-31
A2: Treasury Shares Number | D2: 0
A3: Ordinary Shares Number | B3: 1867392000 | C3: 1866647000 | D3: 1659823962 | E3: 1659823962
A4: Share Issued | B4: 1867392000 | C4: 1866647000 | D4: 1659823962 | E4: 1659823962
A5: Total Debt | B5: 31938557000 | C5: 24655782000 | D5: 20421953000 | E5: 14548230000
A6: Tangible Book Value | B6: 60803760000 | C6: 60869806000 | D6: 45447898000 | E6: 45082590000
A7: Invested Capital | B7: 92256620000 | C7: 85088598000 | D7: 63696465000 | E7: 57337873000
A8: Working Capital | B8: 15292961000 | C8: 64835937000 | D8: 29971432000 | E8: 25162009000
A9: Net Tangible Assets | B9: 60803760000 | C9: 60869806000 | D9: 45447898000 | E9: 45082590000
A10: Capital Lease Obligations | B10: 3558703000 | C10: 3671610000 | D10: 2438528000 | E10: 2560861000
A11: Common Stock Equity | B11: 63876766000 | C11: 64104426000 | D11: 45713040000 | E11: 45350504000
A12: Total Capitalization | B12: 81736910000 | C12: 85088598000 | D12: 63696465000 | E12: 57337873000
A13: Total Equity Gross Minority Interest | B13: 83589527000 | C13: 68667025000 | D13: 45713040000 | E13: 45350504000
A14: Minority Interest | B14: 19712761000 | C14: 4562599000 | D14: 0
A15: Stockholders Equity | B15: 63876766000 | C15: 64104426000 | D15: 45713040000 | E15: 45350504000
A16: Other Equity Interest | B16: -912834000 | C16: -1036807000 | D16: 478147000 | E16: 150047000
A17: Retained Earnings | B17: 16615252000 | C17: 17826712000 | D17: 18889367000 | E17: 18407787000
A18: Additional Paid In Capital | B18: 19015223000 | C18: 18865089000 | D18: 913754000 | E18: 914062000
A19: Capital Stock | B19: 18670782000 | C19: 18666467000 | D19: 16389823000 | E19: 16389823000
A20: Common Stock | B20: 18670782000 | C20: 18666467000 | D20: 16389823000 | E20: 16389823000
A21: Total Liabilities Net Minority Interest | B21: 116879251000 | C21: 80038677000 | D21: 56737003000 | E21: 55589415000
A22: Total Non Current Liabilities Net Minority Interest | B22: 65275006000 | C22: 58663435000 | D22: 36629780000 | E22: 34495937000
A23: Other Non Current Liabilities | B23: 1368938000 | C23: 3074220000 | D23: 4632958000 | E23: 6056600000
A24: Non Current Pension And Other Postretirement Benefit Plans | B24: 202430000 | C24: 255863000 | D24: 302690000 | E24: 372898000
A25: Tradeand Other Payables Non Current | B25: 707490000 | C25: 2211840000
A26: Non Current Deferred Revenue | B26: 40178843000 | C26: 27256837000 | D26: 10444291000 | E26: 13133211000
A27: Non Current Deferred Taxes Liabilities | B27: 1634966000 | C27: 1454349000 | D27: 1052730000 | E27: 604135000
A28: Long Term Debt And Capital Lease Obligation | B28: 21182339000 | C28: 24410326000 | D28: 20197111000 | E28: 14329093000
A29: Long Term Capital Lease Obligation | B29: 3322195000 | C29: 3426154000 | D29: 2213686000 | E29: 2341724000
A30: Long Term Debt | B30: 17860144000 | C30: 20984172000 | D30: 17983425000 | E30: 11987369000
A31: Current Liabilities | B31: 51604245000 | C31: 21375242000 | D31: 20107223000 | E31: 21093478000
A32: Other Current Liabilities | B32: 3430309000 | C32: 3626896000 | D32: 3704126000 | E32: 1917727000
A33: Current Debt And Capital Lease Obligation | B33: 10756218000 | C33: 245456000 | D33: 224842000 | E33: 219137000
A34: Current Capital Lease Obligation | B34: 236508000 | C34: 245456000 | D34: 224842000 | E34: 219137000
A35: Current Debt | B35: 10519710000 | C35: 0 | F35: 0
A36: Pensionand Other Post Retirement Benefit Plans Current | B36: 2037429000 | C36: 1826283000 | D36: 1818740000 | E36: 3397775000
A37: Payables | B37: 29351326000 | C37: 8450722000 | D37: 8191998000 | E37: 11440367000
A38: Other Payable | B38: 26510259000 | C38: 5745941000 | D38: 5005353000 | E38: 7245204000
A39: Total Tax Payable | B39: 1116863000 | C39: 1288527000 | D39: 2214455000 | E39: 2818351000
A40: Accounts Payable | B40: 1724204000 | C40: 1416254000 | D40: 972190000 | E40: 1376812000
...

Sheet Balance sheet (quarterly)
A1: Line item | B1: 2025-12-31 | C1: 2025-06-30 | D1: 2025-03-31 | E1: 2024-12-31
A2: Ordinary Shares Number | B2: 1867392000 | C2: 1867392000 | D2: 1866540000 | E2: 1866647000
A3: Share Issued | B3: 1867392000 | C3: 1867392000 | D3: 1866540000 | E3: 1866647000
A4: Total Debt | B4: 31938557000 | C4: 27799260000 | D4: 24776685000 | E4: 24655782000
A5: Tangible Book Value | B5: 60803760000 | C5: 55090562000 | D5: 63508848000 | E5: 60869806000
A6: Invested Capital | B6: 92256620000 | C6: 82269511000 | D6: 87847528000 | E6: 85088598000
A7: Working Capital | B7: 15292961000 | C7: 41278675000 | D7: 57953650000 | E7: 64835937000
A8: Net Tangible Assets | B8: 60803760000 | C8: 55090562000 | D8: 63508848000 | E8: 60869806000
A9: Capital Lease Obligations | B9: 3558703000 | C9: 3470492000 | D9: 3691522000 | E9: 3671610000
A10: Common Stock Equity | B10: 63876766000 | C10: 57940743000 | D10: 66762365000 | E10: 64104426000
A11: Total Capitalization | B11: 81736910000 | C11: 79027122000 | D11: 87847528000 | E11: 85088598000
A12: Total Equity Gross Minority Interest | B12: 83589527000 | C12: 64022306000 | D12: 72074442000 | E12: 68667025000
A13: Minority Interest | B13: 19712761000 | C13: 6081563000 | D13: 5312077000 | E13: 4562599000
... A33: Current Capital Lease Obligation | B33: 236508000 | C33: 229312000 | D33: 239371000 | E33: 245456000
A34: Current Debt | B34: 10519710000 | C34: 3242389000 | E34: 0
A35: Pensionand Other Post Retirement Benefit Plans Current | B35: 2037429000 | C35: 2579783000 | D35: 2222932000 | E35: 1826283000
A36: Payables | B36: 29351326000 | C36: 21031601000 | D36: 9816925000 | E36: 8450722000
A37: Other Payable | B37: 26510259000 | C37: 10167489000 | D37: 6935794000 | E37: 5745941000
A38: Dividends Payable | C38: 8399910000
A39: Total Tax Payable | B39: 1116863000 | C39: 1161624000 | D39: 1563057000 | E39: 1288527000
A40: Accounts Payable | B40: 1724204000 | C40: 1302578000 | D40: 1318074000 | E40: 1416254000
A41: Total Assets | B41: 200468778000 | C41: 157093291000 | D41: 154428750000 | E41: 148705702000
A42: Total Non Current Assets | B42: 133571572000 | C42: 77990972000 | D42: 72502329000 | E42: 62494523000
A43: Other Non Current Assets | B43: 1312055000 | C43: 1442175000 | D43: 1498999000 | E43: 1493517000
A44: Non Current Prepaid Assets | B44: 13752000 | C44: 10068000 | D44: 7203000 | E44: 5524000
A45: Non Current Deferred Taxes Assets | B45: 2171645000 | C45: 1932523000 | D45: 2258246000 | E45: 2105565000
A46: Investmentin Financial Assets | B46: 6985258000 | C46: 5321857000 | D46: 4927612000 | E46: 4887296000
A47: Available For Sale Securities | B47: 6985258000 | C47: 5321857000 | D47: 4927612000 | E47: 4887296000
A48: Long Term Equity Investment | B48: 2435178000 | C48: 2491482000 | D48: 2542240000 | E48: 2561011000
A49: Goodwill And Other Intangible Assets | B49: 3073006000 | C49: 2850181000 | D49: 3253517000 | E49: 3234620000
A50: Net PPE | B50: 117580678000 | C50: 63942686000 | D50: 58014512000 | E50: 48206990000
... A63: Cash And Cash Equivalents | B63: 39076140000 | C63: 57434879000 | D63: 57037194000 | E63: 57819705000

Sheet Cash flow (annual)
A1: Line item | B1: 2025-12-31 | C1: 2024-12-31 | D1: 2023-12-31 | E1: 2022-12-31 | F1: 2021-12-31
A2: Free Cash Flow | B2: -38538803000 | C2: 8778130000 | D2: 1731417000 | E2: 15062774000
A3: Repayment Of Debt | E3: 0 | F3: -2274504000
A4: Issuance Of Debt | B4: 7518636000 | C4: 3000000000 | D4: 6000000000 | E4: 7000000000
A5: Issuance Of Capital Stock | B5: 0 | C5: 17600000000 | D5: 0
A6: Capital Expenditure | B6: -63978031000 | C6: -15952931000 | D6: -6900092000 | E6: -18863822000
A7: End Cash Position | B7: 39634973000 | C7: 60695212000 | D7: 29842442000 | E7: 30857283000
A8: Beginning Cash Position | B8: 60695212000 | C8: 29842442000 | D8: 30857283000 | E8: 16386567000
A9: Effect Of Exchange Rate Changes | B9: -248515000 | C9: 290509000 | D9: 72176000 | E9: 574900000
A10: Changes In Cash | B10: -20811724000 | C10: 30562261000 | D10: -1087017000 | E10: 13895816000
A11: Financing Cash Flow | B11: 13459626000 | C11: 17529718000 | D11: -1358684000 | E11: 4172793000
A12: Net Other Financing Charges | B12: 14651799000 | C12: 4524069000 | D12: 237881000 | E12: 4781289000
A13: Cash Dividends Paid | B13: -8399910000 | C13: -7375420000 | D13: -7375420000 | E13: -7375420000
A14: Net Common Stock Issuance | B14: 0 | C14: 17600000000 | D14: 0
A15: Common Stock Issuance | B15: 0 | C15: 17600000000 | D15: 0
A16: Net Issuance Payments Of Debt | B16: 7518636000 | C16: 3000000000 | D16: 6000000000 | E16: 7000000000
A17: Net Short Term Debt Issuance | B17: 5518636000 | C17: 0 | E17: 0 | F17: -2274504000
A18: Short Term Debt Payments | E18: 0 | F18: -2274504000
A19: Short Term Debt Issuance | B19: 5518636000 | C19: 0
A20: Net Long Term Debt Issuance | B20: 2000000000 | C20: 3000000000 | D20: 6000000000 | E20: 7000000000
A21: Long Term Debt Issuance | B21: 2000000000 | C21: 3000000000 | D21: 6000000000 | E21: 7000000000
A22: Investing Cash Flow | B22: -59710578000 | C22: -11698518000 | D22: -8359842000 | E22: -24203573000
A23: Net Other Investing Changes | B23: 3042778000 | C23: -138113000 | D23: 97336000 | E23: -819746000
A24: Dividends Received Cfi | B24: 40702000 | C24: 34785000 | D24: 28873000 | E24: 32385000
A25: Net Investment Purchase And Sale | B25: 1183379000 | C25: 6836874000 | D25: -2031180000 | E25: -4631171000
A26: Sale Of Investment | B26: 140000000 | C26: 1426861000 | D26: 1133782000 | E26: 888500000
A27: Purchase Of Investment | B27: 1043379000 | C27: 5410013000 | D27: -3164962000 | E27: -5519671000
A28: Net Business Purchase And Sale | B28: -454000 | C28: -2480000000 | D28: 405181000 | E28: 78165000
A29: Sale Of Business | C29: 0 | D29: 405181000 | E29: 78165000 | F29: 0
A30: Purchase Of Business | B30: -454000 | C30: -2480000000 | D30: 0
A31: Net Intangibles Purchase And Sale | B31: -713162000 | C31: -29210000 | D31: -121257000 | E31: -141236000
A32: Purchase Of Intangibles | B32: -713162000 | C32: -29210000 | D32: -121257000 | E32: -141236000
A33: Net PPE Purchase And Sale | B33: -63263821000 | C33: -15922854000 | D33: -6738795000 | E33: -18721970000
A34: Sale Of PPE | B34: 1048000 | C34: 867000 | D34: 40040000 | E34: 616000
A35: Purchase Of PPE | B35: -63264869000 | C35: -15923721000 | D35: -6778835000 | E35: -18722586000
A36: Operating Cash Flow | B36: 25439228000 | C36: 24731061000 | D36: 8631509000 | E36: 33926596000
A37: Taxes Refund Paid | B37: -1512112000 | C37: -2644558000 | D37: -2394419000 | E37: -2904308000
A38: Interest Received Cfo | B38: 1792061000 | C38: 1876402000 | D38: 1422983000 | E38: 601023000
A39: Interest Paid Cfo | B39: -259635000 | C39: -298975000 | D39: -204729000 | E39: -128903000
A40: Change In Working Capital | B40: 8250666000 | C40: 9900302000 | D40: -3818569000 | E40: 12066777000
...

Sheet Cash flow (quarterly)
A1: Line item | B1: 2025-12-31 | C1: 2025-06-30 | D1: 2025-03-31 | E1: 2024-12-31
A2: Free Cash Flow | B2: -20331536000 | C2: -6708045000 | D2: -2319726000 | E2: 7155604000
A3: Issuance Of Debt | B3: 1815747000 | C3: 3242389000 | D3: 100000000 | E3: -961187000
A4: Capital Expenditure | B4: -28023213000 | C4: -8679200000 | D4: -10230837000 | E4: -5765116000
A5: End Cash Position | B5: 39634973000 | C5: 57779261000 | D5: 59787318000 | E5: 60695212000
A6: Beginning Cash Position | B6: 48392990000 | C6: 59787318000 | D6: 60695212000 | E6: 37218250000
A7: Effect Of Exchange Rate Changes | B7: -57317000 | C7: -692629000 | D7: 229354000 | E7: 179873000
A8: Changes In Cash | B8: -8700700000 | C8: -1315428000 | D8: -1137248000 | E8: 23297089000
A9: Financing Cash Flow | B9: 10354131000 | C9: 4747333000 | D9: 466937000 | E9: 16506167000
A10: Net Other Financing Charges | B10: 8617393000 | C10: 1565987000 | D10: 432826000 | E10: -87738000
A11: Cash Dividends Paid | B11: 0 | E11: 0
A12: Net Issuance Payments Of Debt | B12: 1815747000 | C12: 3242389000 | D12: 100000000 | E12: -961187000
A13: Net Short Term Debt Issuance | B13: 815747000
A14: Short Term Debt Issuance | B14: 815747000
A15: Net Long Term Debt Issuance | B15: 1000000000 | C15: 0 | D15: 100000000 | E15: 0
A16: Long Term Debt Issuance | B16: 1000000000 | C16: 0 | D16: 100000000 | E16: 0
A17: Investing Cash Flow | B17: -26746508000 | C17: -8033916000 | D17: -9515296000 | E17: -6129798000
A18: Net Other Investing Changes | B18: 1859343000 | C18: 3558000 | D18: -1748000 | E18: 305000
A19: Dividends Received Cfi | B19: 0 | E19: 0
A20: Net Investment Purchase And Sale | B20: -583686000 | C20: 612853000 | D20: 717743000 | E20: -365854000
A21: Sale Of Investment | B21: 0 | C21: 0 | D21: 140000000 | E21: 0
A22: Purchase Of Investment | B22: -583686000 | C22: 612853000 | D22: 577743000 | E22: -365854000
A23: Net Business Purchase And Sale | B23: 0 | C23: 0 | D23: -454000 | E23: 0
A24: Purchase Of Business | B24: 0 | C24: 0 | D24: -454000 | E24: 0
A25: Net Intangibles Purchase And Sale | B25: -1639000 | C25: -1052000 | D25: -6592000 | E25: -11689000
A26: Purchase Of Intangibles | B26: -1639000 | C26: -1052000 | D26: -6592000 | E26: -11689000
A27: Net PPE Purchase And Sale | B27: -28020526000 | C27: -8678148000 | D27: -10224245000 | E27: -5752560000
A28: Sale Of PPE | E28: 867000
A29: Purchase Of PPE | B29: -28021574000 | C29: -8678148000 | D29: -10224245000 | E29: -5753427000
A30: Operating Cash Flow | B30: 7691677000 | C30: 1971155000 | D30: 7911111000 | E30: 12920720000
A31: Taxes Refund Paid | B31: -37946000 | C31: -511225000 | D31: -46234000 | E31: -29346000
A32: Interest Received Cfo | B32: 401108000 | C32: 491728000 | D32: 420420000 | E32: 430824000
A33: Interest Paid Cfo | B33: -33167000 | C33: -20771000 | D33: -135306000 | E33: -24917000
A34: Change In Working Capital | B34: 3110757000 | C34: -2218041000 | D34: 3228398000 | E34: 8045226000
A35: Change In Other Current Liabilities | B35: 464425000 | C35: 422678000 | D35: 718855000 | E35: 538519000
A36: Change In Other Current Assets | B36: 4717039000 | C36: -2587206000 | D36: 3496902000 | E36: 8000767000
A37: Change In Payable | B37: 1573103000 | C37: 41923000 | D37: -135593000 | E37: 22018000
A38: Change In Prepaid Assets | B38: -1746078000 | C38: 158754000 | D38: -62119000 | E38: 302989000
A39: Change In Inventory | B39: -604265000 | C39: -273653000 | D39: 85311000 | E39: -433427000
A40: Change In Receivables | B40: -1292769000 | C40: 20210000 | D40: -809008000 | E40: -385028000
...

Sheet Data flags
A1: Field | B1: Issue
A2: FY Summary | B2: 'Net Debt' not found in statements — left blank
