Workbook

Sheet Summary
A1: Field | B1: Value | C1: Source / formula
A2: Ticker | B2: NXT | C2: input
A3: Name | B3: Nextpower Inc. | C3: yfinance info.longName
A4: Sector | B4: Technology | C4: yfinance info.sector
A5: Industry | B5: Solar | C5: yfinance info.industry
A6: Market cap ($) | B6: 19159877632 | C6: yfinance info.marketCap
A7: Enterprise value ($) | B7: 17826179072 | C7: yfinance info.enterpriseValue
A8: Trailing P/E | B8: 32.78646 | C8: yfinance info.trailingPE
A9: Forward P/E | B9: 21.56956 | C9: yfinance info.forwardPE
A10: P/S (TTM) | B10: 5.3829107 | C10: yfinance
A11: Gross margin (TTM) | B11: 0.2192 | C11: yfinance info.grossMargins
A12: Operating margin (TTM) | B12: 0.18155001 | C12: yfinance info.operatingMargins
A13: Net margin (TTM) | B13: 0.16459998 | C13: yfinance info.profitMargins
A14: ROE | B14: 0.29571 | C14: yfinance info.returnOnEquity
A15: Revenue growth (YoY) | B15: -0.047 | C15: yfinance info.revenueGrowth
A16: Total cash ($) | B16: 1146275968 | C16: yfinance info.totalCash
A17: Total debt ($) | B17: 52900000 | C17: yfinance info.totalDebt
... A20: Current price ($) | B20: 125.9 | C20: yfinance info.currentPrice
A21: FCF yield | B21: =IFERROR(B18/B6,"") | C21: =B18/B6
A22: FCF / EV | B22: =IFERROR(B18/B7,"") | C22: =B18/B7

Sheet FY Summary
A1: Fiscal-year summary (GAAP, $ except where noted) | B1: FY-3 | C1: FY-2 | D1: FY-1 | E1: TTM | F1: Source / formula
A2: Fiscal period end | B2: 2024-03-31 | C2: 2025-03-31 | D2: 2026-03-31 | E2: TTM → 2026-03-31 | F2: annual statement headers; TTM = Σ last 4 quarters
A3: Revenue | B3: ='Income stmt (annual)'!D41 | C3: ='Income stmt (annual)'!C41 | D3: ='Income stmt (annual)'!B41 | E3: =SUM('Income stmt (quarterly)'!B47:E47) | F3: Total Revenue
A4: Gross profit | B4: ='Income stmt (annual)'!D39 | C4: ='Income stmt (annual)'!C39 | D4: ='Income stmt (annual)'!B39 | E4: =SUM('Income stmt (quarterly)'!B45:E45) | F4: Gross Profit (GAAP)
A5: Gross margin % | B5: =IFERROR(B4/B3,"") | C5: =IFERROR(C4/C3,"") | D5: =IFERROR(D4/D3,"") | E5: =IFERROR(E4/E3,"") | F5: GAAP = gross profit / revenue
A6: Operating income | B6: ='Income stmt (annual)'!D35 | C6: ='Income stmt (annual)'!C35 | D6: ='Income stmt (annual)'!B35 | E6: =SUM('Income stmt (quarterly)'!B40:E40) | F6: Operating Income
A7: Operating margin % | B7: =IFERROR(B6/B3,"") | C7: =IFERROR(C6/C3,"") | D7: =IFERROR(D6/D3,"") | E7: =IFERROR(E6/E3,"") | F7: =operating income / revenue
A8: EBITDA | B8: ='Income stmt (annual)'!D8 | C8: ='Income stmt (annual)'!C8 | D8: ='Income stmt (annual)'!B8 | E8: =SUM('Income stmt (quarterly)'!B10:E10) | F8: EBITDA
A9: Free cash flow | B9: ='Cash flow (annual)'!D2 | C9: ='Cash flow (annual)'!C2 | D9: ='Cash flow (annual)'!B2 | E9: =SUM('Cash flow (quarterly)'!B2:E2) | F9: FCF = OCF − capex
A10: FCF margin % | B10: =IFERROR(B9/B3,"") | C10: =IFERROR(C9/C3,"") | D10: =IFERROR(D9/D3,"") | E10: =IFERROR(E9/E3,"") | F10: =FCF / revenue
A11: Capex | B11: =-'Cash flow (annual)'!D7 | C11: =-'Cash flow (annual)'!C7 | D11: =-'Cash flow (annual)'!B7 | E11: =-SUM('Cash flow (quarterly)'!B6:E6) | F11: Capex (shown positive)
A12: Capex / revenue % | B12: =IFERROR(B11/B3,"") | C12: =IFERROR(C11/C3,"") | D12: =IFERROR(D11/D3,"") | E12: =IFERROR(E11/E3,"") | F12: =capex / revenue
A13: Net debt | B13: ='Balance sheet (annual)'!D4 | C13: ='Balance sheet (annual)'!C4 | D13: ='Balance sheet (annual)'!B4 | E13: ='Balance sheet (annual)'!B4 | F13: Net debt; TTM = MRQ
A14: Net debt / EBITDA | B14: =IFERROR(B13/B8,"") | C14: =IFERROR(C13/C8,"") | D14: =IFERROR(D13/D8,"") | E14: =IFERROR(E13/E8,"") | F14: =net debt / EBITDA
A15: Share count (period-end, M) | B15: ='Balance sheet (annual)'!D2/1e6 | C15: ='Balance sheet (annual)'!C2/1e6 | D15: ='Balance sheet (annual)'!B2/1e6 | E15: ='Balance sheet (quarterly)'!B2/1e6 | F15: shares ÷ 1e6; TTM = MRQ
A16: Share count YoY % | C16: =IFERROR(C15/B15-1,"") | D16: =IFERROR(D15/C15-1,"") | E16: =IFERROR(E15/D15-1,"") | F16: vs prior period

Sheet Income stmt (annual)
A1: Line item | B1: 2026-03-31 | C1: 2025-03-31 | D1: 2024-03-31 | E1: 2023-03-31 | F1: 2022-03-31
A2: Tax Effect Of Unusual Items | B2: 0 | C2: 0 | D2: 0 | E2: 0
A3: Tax Rate For Calcs | B3: 0.179 | C3: 0.201801 | D3: 0.183853 | E3: 0.282
A4: Normalized EBITDA | B4: 747051000 | C4: 674519000 | D4: 626180000 | E4: 175542000
A5: Net Income From Continuing Operation Net Minority Interest | B5: 585883000 | C5: 509168000 | D5: 306241000 | E5: 118887000
A6: Reconciled Depreciation | B6: 30602000 | C6: 13407000 | D6: 4363000 | E6: 4626000
A7: Reconciled Cost Of Revenue | B7: 2399295000 | C7: 1950372000 | D7: 1686792000 | E7: 1615164000
A8: EBITDA | B8: 747051000 | C8: 674519000 | D8: 626180000 | E8: 175542000
A9: EBIT | B9: 716449000 | C9: 661112000 | D9: 621817000 | E9: 170916000
A10: Net Interest Income | B10: -2623000 | C10: -13096000 | D10: -13820000 | E10: -1833000
A11: Interest Expense | B11: 2623000 | C11: 13096000 | D11: 13820000 | E11: 1833000
A12: Normalized Income | B12: 585883000 | C12: 509168000 | D12: 306241000 | E12: 118887000
A13: Net Income From Continuing And Discontinued Operation | B13: 585883000 | C13: 509168000 | D13: 306241000 | E13: 118887000
... A15: Total Operating Income As Reported | B15: 697266000 | C15: 639112000 | D15: 587118000 | E15: 168485000
A16: Diluted Average Shares | C16: 149276000 | D16: 147284330 | E16: 145834762 | F16: 41879190
A17: Basic Average Shares | C17: 143539000 | D17: 77067639 | E17: 45869190 | F17: 41879190
A18: Diluted EPS | C18: 3.47 | D18: 3.37 | E18: 0.02 | F18: 0
A19: Basic EPS | C19: 3.55 | D19: 3.97 | E19: 0.02 | F19: 0
A20: Diluted NI Availto Com Stockholders | B20: 585883000 | C20: 509168000 | D20: 306241000 | E20: 1143000
A21: Net Income Common Stockholders | B21: 585883000 | C21: 509168000 | D21: 306241000 | E21: 1143000
A22: Otherunder Preferred Stock Dividend | C22: 0 | D22: 0 | E22: 117744000 | F22: 50913000
A23: Net Income | B23: 585883000 | C23: 509168000 | D23: 306241000 | E23: 118887000
A24: Minority Interests | B24: 0 | C24: -8078000 | D24: -189974000 | E24: -2446000
A25: Net Income Including Noncontrolling Interests | B25: 585883000 | C25: 517246000 | D25: 496215000 | E25: 121333000
A26: Net Income From Tax Loss Carryforward | E26: -117744000 | F26: -50913000
A27: Net Income Continuous Operations | B27: 585883000 | C27: 517246000 | D27: 496215000 | E27: 121333000
A28: Tax Provision | B28: 127943000 | C28: 130770000 | D28: 111782000 | E28: 47750000
A29: Pretax Income | B29: 713826000 | C29: 648016000 | D29: 607997000 | E29: 169083000
A30: Other Income Expense | B30: 19183000 | C30: 22000000 | D30: 34699000 | E30: 2431000
A31: Other Non Operating Income Expenses | B31: 19183000 | C31: 22000000 | D31: 34699000 | E31: 2431000
A32: Net Non Operating Interest Income Expense | B32: -2623000 | C32: -13096000 | D32: -13820000 | E32: -1833000
A33: Total Other Finance Cost | E33: -598000 | F33: 799000
A34: Interest Expense Non Operating | B34: 2623000 | C34: 13096000 | D34: 13820000 | E34: 1833000
A35: Operating Income | B35: 697266000 | C35: 639112000 | D35: 587118000 | E35: 168485000
A36: Operating Expense | B36: 462829000 | C36: 369713000 | D36: 225931000 | E36: 118488000
A37: Research And Development | B37: 120909000 | C37: 79392000 | D37: 42360000 | E37: 21619000
A38: Selling General And Administration | B38: 341920000 | C38: 290321000 | D38: 183571000 | E38: 96869000
A39: Gross Profit | B39: 1160095000 | C39: 1008825000 | D39: 813049000 | E39: 286973000
A40: Cost Of Revenue | B40: 2399295000 | C40: 1950372000 | D40: 1686792000 | E40: 1615164000
A41: Total Revenue | B41: 3559390000 | C41: 2959197000 | D41: 2499841000 | E41: 1902137000
...

Sheet Income stmt (quarterly)
A1: Line item | B1: 2026-03-31 | C1: 2025-12-31 | D1: 2025-09-30 | E1: 2025-06-30 | F1: 2025-03-31 | G1: 2024-12-31 | H1: 2024-09-30
A2: Tax Effect Of Unusual Items | B2: 0 | C2: -1446900 | D2: -764400 | E2: -53100 | F2: 0
A3: Tax Rate For Calcs | B3: 0.056579 | C3: 0.273 | D3: 0.196 | E3: 0.177 | F3: 0.205616
A4: Normalized EBITDA | B4: 168989000 | C4: 194574000 | D4: 194716000 | E4: 198272000 | F4: 206123000
A5: Total Unusual Items | C5: -5300000 | D5: -3900000 | E5: -300000 | G5: 3600000 | H5: 2400000
A6: Total Unusual Items Excluding Goodwill | C6: -5300000 | D6: -3900000 | E6: -300000 | G6: 3600000 | H6: 2400000
A7: Net Income From Continuing Operation Net Minority Interest | B7: 150603000 | C7: 131236000 | D7: 146861000 | E7: 157183000 | F7: 156794000
A8: Reconciled Depreciation | B8: 9016000 | C8: 8436000 | D8: 7361000 | E8: 5789000 | F8: 5108000
A9: Reconciled Cost Of Revenue | B9: 583140000 | C9: 621220000 | D9: 612408000 | E9: 582527000 | F9: 618655000
A10: EBITDA | B10: 168989000 | C10: 189274000 | D10: 190816000 | E10: 197972000 | F10: 206123000
A11: EBIT | B11: 159973000 | C11: 180838000 | D11: 183455000 | E11: 192183000 | F11: 201015000
A12: Net Interest Income | B12: -338000 | C12: 9261000 | D12: 5670000 | E12: 5084000 | F12: -16053000
A13: Interest Expense | B13: 338000 | C13: 339000 | D13: 730000 | E13: 1216000 | F13: 2353000
A14: Interest Income | C14: 9600000 | D14: 6400000 | E14: 6300000 | G14: 5800000 | H14: 3300000
A15: Normalized Income | B15: 150603000 | C15: 135089100 | D15: 149996600 | E15: 157429900 | F15: 156794000
A16: Net Income From Continuing And Discontinued Operation | B16: 150603000 | C16: 131236000 | D16: 146861000 | E16: 157183000 | F16: 156794000
A17: Total Expenses | B17: 726931000 | C17: 733247000 | D17: 723923000 | E17: 678023000 | F17: 733435000
A18: Total Operating Income As Reported | B18: 153586000 | C18: 176105000 | D18: 181345000 | E18: 186230000 | F18: 195307000
A19: Diluted Average Shares | B19: 154664000 | C19: 153921000 | D19: 152018000 | E19: 150901000 | F19: 149740000
A20: Basic Average Shares | B20: 148496000 | C20: 148414000 | D20: 148028000 | E20: 147631000 | F20: 144888000
A21: Diluted EPS | B21: 0.97 | C21: 0.85 | D21: 0.97 | E21: 1.04 | F21: 1.05
A22: Basic EPS | B22: 1.01 | C22: 0.88 | D22: 0.99 | E22: 1.06 | F22: 1.08
A23: Diluted NI Availto Com Stockholders | B23: 150603000 | C23: 131236000 | D23: 146861000 | E23: 157183000 | F23: 149736000
A24: Average Dilution Earnings | C24: 0 | G24: 2091000 | H24: 1873000
A25: Net Income Common Stockholders | B25: 150603000 | C25: 131236000 | D25: 146861000 | E25: 157183000 | F25: 156794000
A26: Net Income | B26: 150603000 | C26: 131236000 | D26: 146861000 | E26: 157183000 | F26: 156794000
A27: Minority Interests | B27: 0 | C27: 0 | D27: 0 | E27: 0 | F27: -1020000
A28: Net Income Including Noncontrolling Interests | B28: 150603000 | C28: 131236000 | D28: 146861000 | E28: 157183000 | F28: 157814000
A29: Net Income Continuous Operations | B29: 150603000 | C29: 131236000 | D29: 146861000 | E29: 157183000 | F29: 157814000
A30: Tax Provision | B30: 9032000 | C30: 49263000 | D30: 35864000 | E30: 33784000 | F30: 40848000
A31: Pretax Income | B31: 159635000 | C31: 180499000 | D31: 182725000 | E31: 190967000 | F31: 198662000
A32: Other Income Expense | B32: 6387000 | C32: -4900000 | D32: -4300000 | E32: -347000 | F32: 23808000
A33: Other Non Operating Income Expenses | B33: 6387000 | C33: 400000 | D33: -400000 | E33: -47000 | F33: 20008000
A34: Special Income Charges | D34: -5800000
A35: Write Off | D35: 5800000
A36: Gain On Sale Of Security | C36: -5300000 | D36: 1900000 | E36: -300000 | G36: 3600000 | H36: 2400000
A37: Net Non Operating Interest Income Expense | B37: -338000 | C37: 9261000 | D37: 5670000 | E37: 5084000 | F37: -16053000
A38: Interest Expense Non Operating | B38: 338000 | C38: 339000 | D38: 730000 | E38: 1216000 | F38: 2353000
A39: Interest Income Non Operating | C39: 9600000 | D39: 6400000 | E39: 6300000 | G39: 5800000 | H39: 3300000
A40: Operating Income | B40: 153586000 | C40: 176105000 | D40: 181345000 | E40: 186230000 | F40: 190907000
...

Sheet Balance sheet (annual)
A1: Line item | B1: 2026-03-31 | C1: 2025-03-31 | D1: 2024-03-31 | E1: 2023-03-31 | F1: 2022-03-31
A2: Ordinary Shares Number | B2: 149391483 | C2: 145648231 | D2: 140773223 | E2: 45886065
A3: Share Issued | B3: 149391483 | C3: 145648231 | D3: 140773223 | E3: 45886065
A4: Net Debt | E4: 17139000
A5: Total Debt | D5: 147717000 | E5: 147147000
A6: Tangible Book Value | B6: 1767401000 | C6: 1203871000 | D6: 694314000 | E6: -3342241000
A7: Invested Capital | B7: 2334397000 | C7: 1628130000 | D7: 1108730000 | E7: -2928620000
A8: Working Capital | B8: 1682694000 | C8: 1124474000 | D8: 876749000 | E8: 364839000
A9: Net Tangible Assets | B9: 1767401000 | C9: 1203871000 | D9: 694314000 | E9: -3342241000
A10: Common Stock Equity | B10: 2334397000 | C10: 1628130000 | D10: 961013000 | E10: -3075767000
A11: Total Capitalization | B11: 2334397000 | C11: 1628130000 | D11: 1104980000 | E11: -2928620000
A12: Total Equity Gross Minority Interest | B12: 2334397000 | C12: 1628130000 | D12: 992028000 | E12: 484861000
A13: Minority Interest | C13: 0 | D13: 31015000 | E13: 3560628000 | F13: 0
A14: Stockholders Equity | B14: 2334397000 | C14: 1628130000 | D14: 961013000 | E14: -3075767000
A15: Other Equity Interest | F15: -3035000
A16: Gains Losses Not Affecting Retained Earnings | B16: 183000 | C16: -298000 | D16: 17000 | E16: 0
A17: Other Equity Adjustments | B17: 183000 | C17: -298000 | D17: 17000
A18: Retained Earnings | B18: -1971527000 | C18: -2557410000 | D18: -3066578000 | E18: -3075782000
A19: Additional Paid In Capital | B19: 4305726000 | C19: 4185823000 | D19: 4027560000 | E19: 0
A20: Capital Stock | B20: 15000 | C20: 15000 | D20: 14000 | E20: 15000
A21: Common Stock | B21: 15000 | C21: 15000 | D21: 14000 | E21: 15000
A22: Total Liabilities Net Minority Interest | B22: 1738815000 | C22: 1564386000 | D22: 1526754000 | E22: 934819000
A23: Total Non Current Liabilities Net Minority Interest | B23: 574953000 | C23: 530874000 | D23: 635268000 | E23: 427393000
A24: Other Non Current Liabilities | B24: 472460000 | C24: 434239000 | D24: 421970000 | E24: 280246000
A25: Preferred Securities Outside Stock Equity | E25: 0 | F25: 504168000
A26: Tradeand Other Payables Non Current | E26: 230300000
A27: Non Current Deferred Liabilities | B27: 102493000 | C27: 96635000 | D27: 69331000 | E27: 35800000
A28: Non Current Deferred Revenue | B28: 102493000 | C28: 96635000 | D28: 69331000 | E28: 35800000
A29: Long Term Debt And Capital Lease Obligation | D29: 143967000 | E29: 147147000
A30: Long Term Debt | D30: 143967000 | E30: 147147000
A31: Long Term Provisions | E31: 11800000 | F31: 8800000
A32: Current Liabilities | B32: 1163862000 | C32: 1033512000 | D32: 891486000 | E32: 507426000
A33: Other Current Liabilities | B33: 192747000 | C33: 104086000 | D33: 123148000 | E33: 47589000
A34: Current Deferred Liabilities | B34: 307492000 | C34: 247127000 | D34: 225539000 | E34: 176473000
A35: Current Deferred Revenue | B35: 307492000 | C35: 247127000 | D35: 225539000 | E35: 176473000
A36: Current Debt And Capital Lease Obligation | D36: 3750000
A37: Current Debt | D37: 3750000
A38: Payables And Accrued Expenses | B38: 663623000 | C38: 682299000 | D38: 539049000 | E38: 283364000
A39: Current Accrued Expenses | B39: 130133000 | C39: 97000000 | D39: 82410000 | E39: 59770000
A40: Payables | B40: 533490000 | C40: 585299000 | D40: 456639000 | E40: 223594000
...

Sheet Balance sheet (quarterly)
A1: Line item | B1: 2026-03-31 | C1: 2025-12-31 | D1: 2025-09-30 | E1: 2025-06-30 | F1: 2025-03-31 | G1: 2024-12-31 | H1: 2024-09-30
A2: Ordinary Shares Number | B2: 149391483 | C2: 148447633 | D2: 148382565 | E2: 147963974 | F2: 145648231
A3: Share Issued | B3: 149391483 | C3: 148447633 | D3: 148382565 | E3: 147963974 | F3: 145648231
A4: Total Debt | G4: 145333000 | H4: 146128000
A5: Tangible Book Value | B5: 1767401000 | C5: 1584993000 | D5: 1430315000 | E5: 1293272000 | F5: 1203871000
A6: Invested Capital | B6: 2334397000 | C6: 2150870000 | D6: 1985698000 | E6: 1807144000 | F6: 1628130000
A7: Working Capital | B7: 1682694000 | C7: 1474827000 | D7: 1318869000 | E7: 1200953000 | F7: 1124474000
A8: Net Tangible Assets | B8: 1767401000 | C8: 1584993000 | D8: 1430315000 | E8: 1293272000 | F8: 1203871000
A9: Common Stock Equity | B9: 2334397000 | C9: 2150870000 | D9: 1985698000 | E9: 1807144000 | F9: 1628130000
A10: Total Capitalization | B10: 2334397000 | C10: 2150870000 | D10: 1985698000 | E10: 1807144000 | F10: 1628130000
A11: Total Equity Gross Minority Interest | B11: 2334397000 | C11: 2150870000 | D11: 1985698000 | E11: 1807144000 | F11: 1628130000
A12: Minority Interest | F12: 0 | G12: 18410000 | H12: 16319000
A13: Stockholders Equity | B13: 2334397000 | C13: 2150870000 | D13: 1985698000 | E13: 1807144000 | F13: 1628130000
A14: Gains Losses Not Affecting Retained Earnings | B14: 183000 | C14: -656000 | D14: -737000 | E14: -777000 | F14: -298000
A15: Other Equity Adjustments | B15: 183000 | C15: -656000 | D15: -737000 | E15: -777000 | F15: -298000
A16: Retained Earnings | B16: -1971527000 | C16: -2122130000 | D16: -2253366000 | E16: -2400227000 | F16: -2557410000
A17: Additional Paid In Capital | B17: 4305726000 | C17: 4273641000 | D17: 4239786000 | E17: 4208133000 | F17: 4185823000
A18: Capital Stock | B18: 15000 | C18: 15000 | D18: 15000 | E18: 15000 | F18: 15000
A19: Common Stock | B19: 15000 | C19: 15000 | D19: 15000 | E19: 15000 | F19: 15000
A20: Total Liabilities Net Minority Interest | B20: 1738815000 | C20: 1649196000 | D20: 1683191000 | E20: 1582795000 | F20: 1564386000
A21: Total Non Current Liabilities Net Minority Interest | B21: 574953000 | C21: 564424000 | D21: 563385000 | E21: 550804000 | F21: 530874000
A22: Other Non Current Liabilities | B22: 472460000 | C22: 466844000 | D22: 464503000 | E22: 449352000 | F22: 434239000
A23: Non Current Deferred Liabilities | B23: 102493000 | C23: 97580000 | D23: 98882000 | E23: 101452000 | F23: 96635000
A24: Non Current Deferred Revenue | B24: 102493000 | C24: 97580000 | D24: 98882000 | E24: 101452000 | F24: 96635000
A25: Long Term Debt And Capital Lease Obligation | G25: 138770000 | H25: 140503000
A26: Long Term Debt | G26: 138770000 | H26: 140503000
A27: Current Liabilities | B27: 1163862000 | C27: 1084772000 | D27: 1119806000 | E27: 1031991000 | F27: 1033512000
A28: Other Current Liabilities | B28: 192747000 | C28: 96242000 | D28: 90277000 | E28: 102859000 | F28: 104086000
A29: Current Deferred Liabilities | B29: 307492000 | C29: 321882000 | D29: 372348000 | E29: 261688000 | F29: 247127000
A30: Current Deferred Revenue | B30: 307492000 | C30: 321882000 | D30: 372348000 | E30: 261688000 | F30: 247127000
A31: Current Debt And Capital Lease Obligation | G31: 6563000 | H31: 5625000
A32: Current Debt | G32: 6563000 | H32: 5625000
A33: Payables And Accrued Expenses | B33: 663623000 | C33: 666648000 | D33: 657181000 | E33: 667444000 | F33: 682299000
A34: Current Accrued Expenses | B34: 130133000 | C34: 106573000 | D34: 103573000 | E34: 85990000 | F34: 97000000
A35: Payables | B35: 533490000 | C35: 560075000 | D35: 553608000 | E35: 581454000 | F35: 585299000
A36: Accounts Payable | B36: 533490000 | C36: 560075000 | D36: 553608000 | E36: 581454000 | F36: 585299000
A37: Total Assets | B37: 4073212000 | C37: 3800066000 | D37: 3668889000 | E37: 3389939000 | F37: 3192516000
A38: Total Non Current Assets | B38: 1226656000 | C38: 1240467000 | D38: 1230214000 | E38: 1156995000 | F38: 1034530000
A39: Other Non Current Assets | B39: 69489000 | C39: 72192000 | D39: 76158000 | E39: 59446000 | F39: 51098000
A40: Non Current Deferred Assets | B40: 511815000 | C40: 517646000 | D40: 513745000 | E40: 511255000 | F40: 498778000
...

Sheet Cash flow (annual)
A1: Line item | B1: 2026-03-31 | C1: 2025-03-31 | D1: 2024-03-31 | E1: 2023-03-31 | F1: 2022-03-31
A2: Free Cash Flow | B2: 513634000 | C2: 621873000 | D2: 422813000 | E2: 104486000
A3: Repurchase Of Capital Stock | B3: -395000 | C3: 0 | D3: -552009000 | E3: -693781000
A4: Repayment Of Debt | B4: 0 | C4: -150000000 | D4: 0 | E4: -20000000
A5: Issuance Of Debt | C5: 0 | D5: 0 | E5: 170000000 | F5: 0
A6: Issuance Of Capital Stock | B6: 0 | C6: 0 | D6: 552009000 | E6: 693857000
A7: Capital Expenditure | B7: -49277000 | C7: -33921000 | D7: -6160000 | E7: -3183000
A8: End Cash Position | B8: 1094976000 | C8: 766103000 | D8: 474054000 | E8: 130008000
A9: Beginning Cash Position | B9: 766103000 | C9: 474054000 | D9: 130008000 | E9: 29070000
A10: Effect Of Exchange Rate Changes | F10: 0
A11: Changes In Cash | B11: 328873000 | C11: 292049000 | D11: 344046000 | E11: 100938000
A12: Financing Cash Flow | B12: -47160000 | C12: -177649000 | D12: -78267000 | E12: -3572000
A13: Cash Flow From Continuing Financing Activities | B13: -47160000 | C13: -177649000 | D13: -78267000 | E13: -3572000
A14: Net Other Financing Charges | B14: -46765000 | C14: -27649000 | D14: -78267000 | E14: -153648000
A15: Cash Dividends Paid | E15: 0 | F15: 0
A16: Net Common Stock Issuance | B16: -395000 | C16: 0 | D16: 0 | E16: 76000
A17: Common Stock Payments | B17: -395000 | C17: 0 | D17: -552009000 | E17: -693781000
A18: Common Stock Issuance | B18: 0 | C18: 0 | D18: 552009000 | E18: 693857000
A19: Net Issuance Payments Of Debt | B19: 0 | C19: -150000000 | D19: 0 | E19: 150000000
A20: Net Long Term Debt Issuance | B20: 0 | C20: -150000000 | D20: 0 | E20: 150000000
A21: Long Term Debt Payments | B21: 0 | C21: -150000000 | D21: 0 | E21: -20000000
A22: Long Term Debt Issuance | C22: 0 | D22: 0 | E22: 170000000 | F22: 0
A23: Investing Cash Flow | B23: -186878000 | C23: -186096000 | D23: -6660000 | E23: -3159000
A24: Cash Flow From Continuing Investing Activities | B24: -186878000 | C24: -186096000 | D24: -6660000 | E24: -3159000
A25: Net Other Investing Changes | B25: -8262000 | C25: -7500000 | D25: -500000
A26: Net Business Purchase And Sale | B26: -129339000 | C26: -144675000 | D26: 0 | E26: 0
A27: Purchase Of Business | B27: -129339000 | C27: -144675000 | D27: 0 | E27: 0
A28: Net Intangibles Purchase And Sale | C28: 0 | D28: -500000 | E28: 0 | F28: 0
A29: Purchase Of Intangibles | C29: 0 | D29: -500000 | E29: 0 | F29: 0
A30: Net PPE Purchase And Sale | B30: -49277000 | C30: -33921000 | D30: -6160000 | E30: -3159000
A31: Sale Of PPE | C31: 0 | D31: 0 | E31: 24000 | F31: 167000
A32: Purchase Of PPE | B32: -49277000 | C32: -33921000 | D32: -6160000 | E32: -3183000
A33: Operating Cash Flow | B33: 562911000 | C33: 655794000 | D33: 428973000 | E33: 107669000
A34: Cash Flow From Continuing Operating Activities | B34: 562911000 | C34: 655794000 | D34: 428973000 | E34: 107669000
A35: Change In Working Capital | B35: -211848000 | C35: -1019000 | D35: -92758000 | E35: -79269000
A36: Change In Other Working Capital | B36: 68102000 | C36: 34686000 | D36: 82606000 | E36: 120472000
A37: Change In Other Current Liabilities | B37: 241978000 | C37: -55055000 | D37: -42468000 | E37: 21838000
A38: Change In Other Current Assets | B38: -94299000 | C38: 67916000 | D38: 21244000 | E38: -18984000
A39: Change In Payables And Accrued Expense | B39: -49443000 | C39: 102905000 | D39: 245374000 | E39: -60308000
A40: Change In Payable | B40: -49443000 | C40: 102905000 | D40: 245374000 | E40: -60308000
...

Sheet Cash flow (quarterly)
A1: Line item | B1: 2026-03-31 | C1: 2025-12-31 | D1: 2025-09-30 | E1: 2025-06-30 | F1: 2025-03-31 | G1: 2024-12-31
A2: Free Cash Flow | B2: 153614000 | C2: 118549000 | D2: 171405000 | E2: 70066000 | F2: 227247000
A3: Repurchase Of Capital Stock | F3: 0 | G3: 0
A4: Repayment Of Debt | B4: 0 | C4: 0 | D4: 0 | E4: 0 | F4: -147187000
A5: Issuance Of Capital Stock | F5: 0 | G5: 0
A6: Capital Expenditure | B6: -17814000 | C6: -4731000 | D6: -15474000 | E6: -11258000 | F6: -10080000
A7: End Cash Position | B7: 1094976000 | C7: 952624000 | D7: 845342000 | E7: 743402000 | F7: 766103000
A8: Beginning Cash Position | B8: 952624000 | C8: 845342000 | D8: 743402000 | E8: 766103000 | F8: 693543000
A9: Changes In Cash | B9: 142352000 | C9: 107282000 | D9: 101940000 | E9: -22701000 | F9: 72560000
A10: Financing Cash Flow | B10: -520000 | C10: -197000 | D10: -40489000 | E10: -5954000 | F10: -147187000
A11: Cash Flow From Continuing Financing Activities | B11: -520000 | C11: -197000 | D11: -40489000 | E11: -5954000 | F11: -147187000
A12: Net Other Financing Charges | B12: -125000 | C12: -197000 | D12: -40489000 | E12: -5954000 | F12: 0
A13: Net Common Stock Issuance | F13: 0 | G13: 0
A14: Common Stock Payments | F14: 0 | G14: 0
A15: Common Stock Issuance | F15: 0 | G15: 0
A16: Net Issuance Payments Of Debt | B16: 0 | C16: 0 | D16: 0 | E16: 0 | F16: -147187000
A17: Net Long Term Debt Issuance | B17: 0 | C17: 0 | D17: 0 | E17: 0 | F17: -147187000
A18: Long Term Debt Payments | B18: 0 | C18: 0 | D18: 0 | E18: 0 | F18: -147187000
A19: Investing Cash Flow | B19: -28556000 | C19: -15801000 | D19: -44450000 | E19: -98071000 | F19: -17580000
A20: Cash Flow From Continuing Investing Activities | B20: -28556000 | C20: -15801000 | D20: -44450000 | E20: -98071000 | F20: -17580000
A21: Net Other Investing Changes | B21: -5515000
A22: Net Business Purchase And Sale | B22: -5227000 | C22: -8323000 | D22: -28976000 | E22: -86813000 | F22: -7500000
A23: Purchase Of Business | B23: -5227000 | C23: -8323000 | D23: -28976000 | E23: -86813000 | F23: -7500000
A24: Net PPE Purchase And Sale | B24: -17814000 | C24: -4731000 | D24: -15474000 | E24: -11258000 | F24: -10080000
A25: Purchase Of PPE | B25: -17814000 | C25: -4731000 | D25: -15474000 | E25: -11258000 | F25: -10080000
A26: Operating Cash Flow | B26: 171428000 | C26: 123280000 | D26: 186879000 | E26: 81324000 | F26: 237327000
A27: Cash Flow From Continuing Operating Activities | B27: 171428000 | C27: 123280000 | D27: 186879000 | E27: 81324000 | F27: 237327000
A28: Change In Working Capital | B28: -146465000 | C28: -16392000 | D28: 32657000 | E28: -81648000 | F28: -51755000
A29: Depreciation Amortization Depletion | B29: 9016000 | C29: 8436000 | D29: 7361000 | E29: 5789000 | F29: 5108000
A30: Depreciation And Amortization | B30: 9016000 | C30: 8436000 | D30: 7361000 | E30: 5789000 | F30: 5108000
A31: Amortization Cash Flow | B31: 22353000 | E31: 2059000 | F31: 9664000
A32: Amortization Of Intangibles | B32: 22353000 | E32: 2059000 | F32: 9664000
A33: Depreciation | E33: 3730000
A34: Net Income From Continuing Operations | B34: 150603000 | C34: 131236000 | D34: 146861000 | E34: 157183000 | F34: 157814000

Sheet Data flags
A1: Field | B1: Issue
A2: — | B2: no gaps detected
