Workbook

Sheet Summary
A1: Field | B1: Value | C1: Source / formula
A2: Ticker | B2: TNC | C2: input
A3: Name | B3: Tennant Company | C3: yfinance info.longName
A4: Sector | B4: Industrials | C4: yfinance info.sector
A5: Industry | B5: Specialty Industrial Machinery | C5: yfinance info.industry
A6: Market cap ($) | B6: 1431779072 | C6: yfinance info.marketCap
A7: Enterprise value ($) | B7: 1743479040 | C7: yfinance info.enterpriseValue
A8: Trailing P/E | B8: 50.017857 | C8: yfinance info.trailingPE
A9: Forward P/E | B9: 13.109204 | C9: yfinance info.forwardPE
A10: P/S (TTM) | B10: 1.181921 | C10: yfinance
A11: Gross margin (TTM) | B11: 0.39450002 | C11: yfinance info.grossMargins
A12: Operating margin (TTM) | B12: 0.01746 | C12: yfinance info.operatingMargins
A13: Net margin (TTM) | B13: 0.025510002 | C13: yfinance info.profitMargins
A14: ROE | B14: 0.053319998 | C14: yfinance info.returnOnEquity
A15: Revenue growth (YoY) | B15: 0.027 | C15: yfinance info.revenueGrowth
A16: Total cash ($) | B16: 82600000 | C16: yfinance info.totalCash
A17: Total debt ($) | B17: 392500000 | C17: yfinance info.totalDebt
... A20: Current price ($) | B20: 84.03 | C20: yfinance info.currentPrice
A21: FCF yield | B21: =IFERROR(B18/B6,"") | C21: =B18/B6
A22: FCF / EV | B22: =IFERROR(B18/B7,"") | C22: =B18/B7

Sheet FY Summary
A1: Fiscal-year summary (GAAP, $ except where noted) | B1: FY-3 | C1: FY-2 | D1: FY-1 | E1: TTM | F1: Source / formula
A2: Fiscal period end | B2: 2023-12-31 | C2: 2024-12-31 | D2: 2025-12-31 | E2: TTM → 2026-03-31 | F2: annual statement headers; TTM = Σ last 4 quarters
A3: Revenue | B3: ='Income stmt (annual)'!D45 | C3: ='Income stmt (annual)'!C45 | D3: ='Income stmt (annual)'!B45 | E3: =SUM('Income stmt (quarterly)'!B40:E40) | F3: Total Revenue
A4: Gross profit | B4: ='Income stmt (annual)'!D43 | C4: ='Income stmt (annual)'!C43 | D4: ='Income stmt (annual)'!B43 | E4: =SUM('Income stmt (quarterly)'!B38:E38) | F4: Gross Profit (GAAP)
A5: Gross margin % | B5: =IFERROR(B4/B3,"") | C5: =IFERROR(C4/C3,"") | D5: =IFERROR(D4/D3,"") | E5: =IFERROR(E4/E3,"") | F5: GAAP = gross profit / revenue
A6: Operating income | B6: ='Income stmt (annual)'!D39 | C6: ='Income stmt (annual)'!C39 | D6: ='Income stmt (annual)'!B39 | E6: =SUM('Income stmt (quarterly)'!B34:E34) | F6: Operating Income
A7: Operating margin % | B7: =IFERROR(B6/B3,"") | C7: =IFERROR(C6/C3,"") | D7: =IFERROR(D6/D3,"") | E7: =IFERROR(E6/E3,"") | F7: =operating income / revenue
A8: EBITDA | B8: ='Income stmt (annual)'!D10 | C8: ='Income stmt (annual)'!C10 | D8: ='Income stmt (annual)'!B10 | E8: =SUM('Income stmt (quarterly)'!B10:E10) | F8: EBITDA
A9: Free cash flow | B9: ='Cash flow (annual)'!D2 | C9: ='Cash flow (annual)'!C2 | D9: ='Cash flow (annual)'!B2 | E9: =SUM('Cash flow (quarterly)'!B2:E2) | F9: FCF = OCF − capex
A10: FCF margin % | B10: =IFERROR(B9/B3,"") | C10: =IFERROR(C9/C3,"") | D10: =IFERROR(D9/D3,"") | E10: =IFERROR(E9/E3,"") | F10: =FCF / revenue
A11: Capex | B11: =-'Cash flow (annual)'!D7 | C11: =-'Cash flow (annual)'!C7 | D11: =-'Cash flow (annual)'!B7 | E11: =-SUM('Cash flow (quarterly)'!B6:E6) | F11: Capex (shown positive)
A12: Capex / revenue % | B12: =IFERROR(B11/B3,"") | C12: =IFERROR(C11/C3,"") | D12: =IFERROR(D11/D3,"") | E12: =IFERROR(E11/E3,"") | F12: =capex / revenue
A13: Net debt | B13: ='Balance sheet (annual)'!D5 | C13: ='Balance sheet (annual)'!C5 | D13: ='Balance sheet (annual)'!B5 | E13: ='Balance sheet (quarterly)'!B5 | F13: Net debt; TTM = MRQ
A14: Net debt / EBITDA | B14: =IFERROR(B13/B8,"") | C14: =IFERROR(C13/C8,"") | D14: =IFERROR(D13/D8,"") | E14: =IFERROR(E13/E8,"") | F14: =net debt / EBITDA
A15: Share count (period-end, M) | B15: ='Balance sheet (annual)'!D3/1e6 | C15: ='Balance sheet (annual)'!C3/1e6 | D15: ='Balance sheet (annual)'!B3/1e6 | E15: ='Balance sheet (quarterly)'!B3/1e6 | F15: shares ÷ 1e6; TTM = MRQ
A16: Share count YoY % | C16: =IFERROR(C15/B15-1,"") | D16: =IFERROR(D15/C15-1,"") | E16: =IFERROR(E15/D15-1,"") | F16: vs prior period

Sheet Income stmt (annual)
A1: Line item | B1: 2025-12-31 | C1: 2024-12-31 | D1: 2023-12-31 | E1: 2022-12-31 | F1: 2021-12-31
A2: Tax Effect Of Unusual Items | B2: -413989.64 | C2: 20133.588 | D2: 34800 | E2: 415000
A3: Tax Rate For Calcs | B3: 0.243523 | C3: 0.201336 | D3: 0.116 | E3: 0.166
A4: Normalized EBITDA | B4: 127300000 | C4: 168900000 | D4: 188100000 | E4: 132800000
A5: Total Unusual Items | B5: -1700000 | C5: 100000 | D5: 300000 | E5: 2500000
A6: Total Unusual Items Excluding Goodwill | B6: -1700000 | C6: 100000 | D6: 300000 | E6: 2500000
A7: Net Income From Continuing Operation Net Minority Interest | B7: 43800000 | C7: 83700000 | D7: 109500000 | E7: 66300000
A8: Reconciled Depreciation | B8: 58700000 | C8: 55100000 | D8: 51100000 | E8: 48700000
A9: Reconciled Cost Of Revenue | B9: 719200000 | C9: 736700000 | D9: 715800000 | E9: 671300000
A10: EBITDA | B10: 125600000 | C10: 169000000 | D10: 188400000 | E10: 135300000
A11: EBIT | B11: 66900000 | C11: 113900000 | D11: 137300000 | E11: 86600000
A12: Net Interest Income | B12: -9000000 | C12: -9100000 | D12: -13500000 | E12: -7100000
A13: Interest Expense | B13: 9000000 | C13: 9100000 | D13: 13500000 | E13: 7100000
... A24: Net Income | B24: 43800000 | C24: 83700000 | D24: 109500000 | E24: 66300000
A25: Minority Interests | F25: 0
A26: Net Income Including Noncontrolling Interests | B26: 43800000 | C26: 83700000 | D26: 109500000 | E26: 66300000
A27: Net Income Continuous Operations | B27: 43800000 | C27: 83700000 | D27: 109500000 | E27: 66300000
A28: Tax Provision | B28: 14100000 | C28: 21100000 | D28: 14300000 | E28: 13200000
A29: Pretax Income | B29: 57900000 | C29: 104800000 | D29: 123800000 | E29: 79500000
A30: Other Income Expense | B30: -1400000 | C30: -400000 | D30: -1300000 | E30: 3100000
A31: Other Non Operating Income Expenses | B31: 300000 | C31: -500000 | D31: -1600000 | E31: 600000
A32: Special Income Charges | C32: 0 | D32: 0 | E32: 3700000 | F32: -1500000
A33: Gain On Sale Of Ppe | C33: 0 | D33: 0 | E33: 3700000 | F33: 9800000
A34: Gain On Sale Of Business | F34: 9800000
A35: Other Special Charges | F35: 11300000
A36: Gain On Sale Of Security | B36: -1700000 | C36: 100000 | D36: 300000 | E36: -1200000
A37: Net Non Operating Interest Income Expense | B37: -9000000 | C37: -9100000 | D37: -13500000 | E37: -7100000
A38: Interest Expense Non Operating | B38: 9000000 | C38: 9100000 | D38: 13500000 | E38: 7100000
A39: Operating Income | B39: 68300000 | C39: 114300000 | D39: 138600000 | E39: 83500000
A40: Operating Expense | B40: 416000000 | C40: 435700000 | D40: 389200000 | E40: 337400000
A41: Research And Development | B41: 41200000 | C41: 43800000 | D41: 36600000 | E41: 31100000
A42: Selling General And Administration | B42: 374800000 | C42: 391900000 | D42: 352600000 | E42: 306300000
A43: Gross Profit | B43: 484300000 | C43: 550000000 | D43: 527800000 | E43: 420900000
A44: Cost Of Revenue | B44: 719200000 | C44: 736700000 | D44: 715800000 | E44: 671300000
A45: Total Revenue | B45: 1203500000 | C45: 1286700000 | D45: 1243600000 | E45: 1092200000
A46: Operating Revenue | B46: 1203500000 | C46: 1286700000 | D46: 1243600000 | E46: 1092200000

Sheet Income stmt (quarterly)
A1: Line item | B1: 2026-03-31 | C1: 2025-12-31 | D1: 2025-09-30 | E1: 2025-06-30 | F1: 2025-03-31 | G1: 2024-12-31
A2: Tax Effect Of Unusual Items | B2: -160000 | C2: -186666.67 | D2: 0 | E2: -208058.61 | F2: -47674.419
A3: Tax Rate For Calcs | B3: 0.4 | C3: 0.266667 | D3: 0.231959 | E3: 0.260073 | F3: 0.238372
A4: Normalized EBITDA | B4: 19600000 | C4: 12100000 | D4: 36500000 | E4: 45000000 | F4: 33700000
A5: Total Unusual Items | B5: -400000 | C5: -700000 | E5: -800000 | F5: -200000 | G5: 0
A6: Total Unusual Items Excluding Goodwill | B6: -400000 | C6: -700000 | E6: -800000 | F6: -200000 | G6: 0
A7: Net Income From Continuing Operation Net Minority Interest | B7: 200000 | C7: -4400000 | D7: 14900000 | E7: 20200000 | F7: 13100000
A8: Reconciled Depreciation | B8: 14900000 | C8: 15300000 | D8: 14700000 | E8: 14700000 | F8: 14000000
A9: Reconciled Cost Of Revenue | B9: 184300000 | C9: 190800000 | D9: 173900000 | E9: 184500000 | F9: 170000000
A10: EBITDA | B10: 19200000 | C10: 11400000 | D10: 36500000 | E10: 44200000 | F10: 33500000
A11: EBIT | B11: 4300000 | C11: -3900000 | D11: 21800000 | E11: 29500000 | F11: 19500000
A12: Net Interest Income | B12: -3400000 | C12: -2100000 | D12: -2400000 | E12: -2200000 | F12: -2300000
A13: Interest Expense | B13: 3400000 | C13: 2100000 | D13: 2400000 | E13: 2200000 | F13: 2300000
A14: Normalized Income | B14: 440000 | C14: -3886666.7 | D14: 14900000 | E14: 20791941 | F14: 13252326
A15: Net Income From Continuing And Discontinued Operation | B15: 200000 | C15: -4400000 | D15: 14900000 | E15: 20200000 | F15: 13100000
A16: Total Expenses | B16: 293000000 | C16: 295800000 | D16: 281000000 | E16: 288000000 | F16: 270400000
A17: Total Operating Income As Reported | B17: 4900000 | C17: -4200000 | D17: 22300000 | E17: 30600000 | F17: 19600000
A18: Diluted Average Shares | B18: 17804603 | C18: 18184728 | D18: 18547724 | E18: 18687918 | F18: 18960007
... A30: Other Non Operating Income Expenses | B30: -200000 | C30: 1000000 | D30: -500000 | E30: -300000 | F30: 100000
A31: Gain On Sale Of Security | B31: -400000 | C31: -700000 | E31: -800000 | F31: -200000 | G31: 0
A32: Net Non Operating Interest Income Expense | B32: -3400000 | C32: -2100000 | D32: -2400000 | E32: -2200000 | F32: -2300000
A33: Interest Expense Non Operating | B33: 3400000 | C33: 2100000 | D33: 2400000 | E33: 2200000 | F33: 2300000
A34: Operating Income | B34: 4900000 | C34: -4200000 | D34: 22300000 | E34: 30600000 | F34: 19600000
A35: Operating Expense | B35: 108700000 | C35: 105000000 | D35: 107100000 | E35: 103500000 | F35: 100400000
A36: Research And Development | B36: 10600000 | C36: 11200000 | D36: 10500000 | E36: 9800000 | F36: 9700000
A37: Selling General And Administration | B37: 98100000 | C37: 93800000 | D37: 96600000 | E37: 93700000 | F37: 90700000
A38: Gross Profit | B38: 113600000 | C38: 100800000 | D38: 129400000 | E38: 134100000 | F38: 120000000
A39: Cost Of Revenue | B39: 184300000 | C39: 190800000 | D39: 173900000 | E39: 184500000 | F39: 170000000
A40: Total Revenue | B40: 297900000 | C40: 291600000 | D40: 303300000 | E40: 318600000 | F40: 290000000
A41: Operating Revenue | B41: 297900000 | C41: 291600000 | D41: 303300000 | E41: 318600000 | F41: 290000000

Sheet Balance sheet (annual)
A1: Line item | B1: 2025-12-31 | C1: 2024-12-31 | D1: 2023-12-31 | E1: 2022-12-31 | F1: 2021-12-31
A2: Treasury Shares Number | D2: 0
A3: Ordinary Shares Number | B3: 17846681 | C3: 18849456 | D3: 18631384 | E3: 18521485
A4: Share Issued | B4: 17846681 | C4: 18849456 | D4: 18631384 | E4: 18521485
A5: Net Debt | B5: 166300000 | C5: 97900000 | D5: 83100000 | E5: 222800000
A6: Total Debt | B6: 330800000 | C6: 254500000 | D6: 242400000 | E6: 332400000
A7: Tangible Book Value | B7: 340400000 | C7: 376500000 | D7: 326500000 | E7: 212400000
A8: Invested Capital | B8: 874100000 | C8: 818300000 | D8: 777000000 | E8: 770800000
A9: Working Capital | B9: 306600000 | C9: 284400000 | D9: 295400000 | E9: 313700000
A10: Net Tangible Assets | B10: 340400000 | C10: 376500000 | D10: 326500000 | E10: 212400000
A11: Capital Lease Obligations | B11: 58300000 | C11: 57000000 | D11: 42400000 | E11: 32400000
A12: Common Stock Equity | B12: 601600000 | C12: 620800000 | D12: 577000000 | E12: 470800000
A13: Total Capitalization | B13: 874100000 | C13: 817500000 | D13: 770700000 | E13: 765600000
A14: Total Equity Gross Minority Interest | B14: 603400000 | C14: 622100000 | D14: 578300000 | E14: 472100000
... A37: Current Capital Lease Obligation | B37: 22100000 | C37: 19000000 | D37: 14500000 | E37: 15000000
A38: Current Debt | C38: 800000 | D38: 6300000 | E38: 5200000 | F38: 4200000
A39: Other Current Borrowings | C39: 800000 | D39: 6300000 | E39: 5200000 | F39: 4200000
A40: Pensionand Other Post Retirement Benefit Plans Current | B40: 40900000 | C40: 53100000 | D40: 67300000 | E40: 44000000
A41: Current Provisions | B41: 6500000 | C41: 6900000 | D41: 7400000 | E41: 7800000
A42: Payables And Accrued Expenses | B42: 181200000 | C42: 174000000 | D42: 142700000 | E42: 154900000
A43: Current Accrued Expenses | B43: 35200000 | C43: 26600000 | D43: 20000000 | E43: 17700000
A44: Payables | B44: 146000000 | C44: 147400000 | D44: 122700000 | E44: 137200000
A45: Total Tax Payable | B45: 18500000 | C45: 20500000 | D45: 11300000 | E45: 11100000
A46: Accounts Payable | B46: 127500000 | C46: 126900000 | D46: 111400000 | E46: 126100000
A47: Total Assets | B47: 1268900000 | C47: 1190100000 | D47: 1113400000 | E47: 1085100000
A48: Total Non Current Assets | B48: 669200000 | C48: 613500000 | D48: 544300000 | E48: 509800000
A49: Other Non Current Assets | B49: 161300000 | C49: 130200000 | D49: 64400000 | E49: 39700000
A50: Goodwill And Other Intangible Assets | B50: 261200000 | C50: 244300000 | D50: 250500000 | E50: 258400000
A51: Other Intangible Assets | B51: 52600000 | C51: 58700000 | D51: 63100000 | E51: 76400000
... A64: Restricted Cash | B64: 200000 | C64: 200000 | D64: 200000 | E64: 200000
A65: Prepaid Assets | F65: 31200000
A66: Inventory | B66: 198500000 | C66: 183800000 | D66: 175900000 | E66: 206600000
A67: Inventories Adjustments Allowances | B67: -54900000 | C67: -50400000 | D67: -47700000 | E67: -49700000
A68: Finished Goods | B68: 149300000 | C68: 138600000 | D68: 127500000 | E68: 153900000
A69: Raw Materials | B69: 104100000 | C69: 95600000 | D69: 96100000 | E69: 102400000
A70: Receivables | B70: 256800000 | C70: 259100000 | D70: 247600000 | E70: 251500000
A71: Accounts Receivable | B71: 256800000 | C71: 259100000 | D71: 247600000 | E71: 251500000
A72: Allowance For Doubtful Accounts Receivable | B72: -10400000 | C72: -7100000 | D72: -7200000 | E72: -6100000
A73: Gross Accounts Receivable | B73: 267200000 | C73: 266200000 | D73: 254800000 | E73: 257600000
A74: Cash Cash Equivalents And Short Term Investments | B74: 106200000 | C74: 99600000 | D74: 116900000 | E74: 77200000
...

Sheet Balance sheet (quarterly)
A1: Line item | B1: 2026-03-31 | C1: 2025-12-31 | D1: 2025-09-30 | E1: 2025-06-30 | F1: 2025-03-31 | G1: 2024-12-31
A2: Treasury Shares Number | E2: 0
A3: Ordinary Shares Number | B3: 17037788 | C3: 17846681 | D3: 18259632 | E3: 18532326 | F3: 18703285
A4: Share Issued | B4: 17037788 | C4: 17846681 | D4: 18259632 | E4: 18532326 | F4: 18703285
A5: Net Debt | B5: 274900000 | C5: 166300000 | D5: 138100000 | E5: 132400000 | F5: 133000000
A6: Total Debt | B6: 392500000 | C6: 330800000 | D6: 273000000 | E6: 247900000 | F6: 249200000
A7: Tangible Book Value | B7: 268800000 | C7: 340400000 | D7: 376700000 | E7: 386500000 | F7: 374300000
A8: Invested Capital | B8: 888700000 | C8: 874100000 | D8: 878400000 | E8: 864400000 | F8: 836900000
A9: Working Capital | B9: 322500000 | C9: 306600000 | D9: 316800000 | E9: 299800000 | F9: 293500000
A10: Net Tangible Assets | B10: 268800000 | C10: 340400000 | D10: 376700000 | E10: 386500000 | F10: 374300000
A11: Capital Lease Obligations | B11: 35000000 | C11: 58300000 | D11: 35500000 | E11: 35400000 | F11: 36700000
A12: Common Stock Equity | B12: 531200000 | C12: 601600000 | D12: 640900000 | E12: 651900000 | F12: 624400000
A13: Total Capitalization | B13: 888700000 | C13: 874100000 | D13: 878400000 | E13: 864400000 | F13: 836900000
A14: Total Equity Gross Minority Interest | B14: 533000000 | C14: 603400000 | D14: 642700000 | E14: 653700000 | F14: 626100000
... A33: Other Current Liabilities | B33: 125500000 | C33: 25800000 | D33: 121600000 | E33: 110800000 | F33: 102300000
A34: Current Deferred Liabilities | C34: 16600000 | G34: 9800000
A35: Current Deferred Revenue | C35: 16600000 | G35: 9800000
A36: Current Debt And Capital Lease Obligation | B36: 400000 | C36: 22100000 | D36: 400000 | E36: 400000 | F36: 500000
A37: Current Capital Lease Obligation | B37: 400000 | C37: 22100000 | D37: 400000 | E37: 400000 | F37: 500000
A38: Current Debt | G38: 800000
A39: Other Current Borrowings | G39: 800000
A40: Line Of Credit | D40: 0 | E40: 0
A41: Pensionand Other Post Retirement Benefit Plans Current | B41: 39600000 | C41: 40900000 | D41: 48900000 | E41: 41300000 | F41: 39300000
A42: Current Provisions | C42: 6500000 | G42: 6900000
A43: Payables And Accrued Expenses | B43: 123100000 | C43: 181200000 | D43: 110600000 | E43: 122300000 | F43: 115300000
A44: Current Accrued Expenses | C44: 35200000 | G44: 26600000
A45: Payables | B45: 123100000 | C45: 146000000 | D45: 110600000 | E45: 122300000 | F45: 115300000
A46: Total Tax Payable | C46: 18500000 | G46: 20500000
A47: Accounts Payable | B47: 123100000 | C47: 127500000 | D47: 110600000 | E47: 122300000 | F47: 115300000
A48: Total Assets | B48: 1276600000 | C48: 1268900000 | D48: 1256900000 | E48: 1241500000 | F48: 1180300000
A49: Total Non Current Assets | B49: 665500000 | C49: 669200000 | D49: 658600000 | E49: 666900000 | F49: 629400000
A50: Other Non Current Assets | B50: 162100000 | C50: 161300000 | D50: 147600000 | E50: 155100000 | F50: 139300000
A51: Goodwill And Other Intangible Assets | B51: 262400000 | C51: 261200000 | D51: 264200000 | E51: 265400000 | F51: 250100000
A52: Other Intangible Assets | B52: 52500000 | C52: 52600000 | D52: 55900000 | E52: 58200000 | F52: 57300000
A53: Goodwill | B53: 209900000 | C53: 208600000 | D53: 208300000 | E53: 207200000 | F53: 192800000
A54: Net PPE | B54: 241000000 | C54: 246700000 | D54: 246800000 | E54: 246400000 | F54: 240000000
A55: Accumulated Depreciation | B55: -297100000 | C55: -289000000 | D55: -351200000 | E55: -342700000 | F55: -323800000
A56: Gross PPE | B56: 538100000 | C56: 535700000 | D56: 598000000 | E56: 589100000 | F56: 563800000
A57: Construction In Progress | C57: 4300000 | G57: 4500000
A58: Other Properties | B58: 538100000 | C58: 56900000 | D58: 598000000 | E58: 589100000 | F58: 563800000
...

Sheet Cash flow (annual)
A1: Line item | B1: 2025-12-31 | C1: 2024-12-31 | D1: 2023-12-31 | E1: 2022-12-31 | F1: 2021-12-31
A2: Free Cash Flow | B2: 42900000 | C2: 68300000 | D2: 164400000 | E2: -54400000
A3: Repurchase Of Capital Stock | B3: -88500000 | C3: -19600000 | D3: -21700000 | E3: -5000000
A4: Repayment Of Debt | B4: -10800000 | C4: -42500000 | D4: -120000000 | E4: -19100000
A5: Issuance Of Debt | B5: 85000000 | C5: 40900000 | D5: 20000000 | E5: 52000000
A6: Issuance Of Capital Stock | F6: 5000000
A7: Capital Expenditure | B7: -22100000 | C7: -21400000 | D7: -24000000 | E7: -29300000
A8: Interest Paid Supplemental Data | B8: 12300000 | C8: 13600000 | D8: 17100000 | E8: 7600000
A9: Income Tax Paid Supplemental Data | B9: 13400000 | C9: 30200000 | D9: 39500000 | E9: 34100000
A10: End Cash Position | B10: 106400000 | C10: 99800000 | D10: 117100000 | E10: 77400000
A11: Beginning Cash Position | B11: 99800000 | C11: 117100000 | D11: 77400000 | E11: 123600000
A12: Effect Of Exchange Rate Changes | B12: 3000000 | C12: -3400000 | D12: -2900000 | E12: -4700000
A13: Changes In Cash | B13: 3600000 | C13: -13900000 | D13: 42600000 | E13: -41500000
A14: Financing Cash Flow | B14: -38700000 | C14: -25200000 | D14: -122600000 | E14: 8100000
A15: Cash Flow From Continuing Financing Activities | B15: -38700000 | C15: -25200000 | D15: -122600000 | E15: 8100000
A16: Net Other Financing Charges | C16: -2200000 | E16: 52000000 | F16: -10900000
A17: Proceeds From Stock Option Exercised | B17: -2500000 | C17: 19600000 | D17: 19000000 | E17: -900000
A18: Cash Dividends Paid | B18: -21900000 | C18: -21400000 | D18: -20100000 | E18: -18900000
A19: Common Stock Dividend Paid | B19: -21900000 | C19: -21400000 | D19: -20100000 | E19: -18900000
A20: Net Common Stock Issuance | B20: -88500000 | C20: -19600000 | D20: -21700000 | E20: -5000000
A21: Common Stock Payments | B21: -88500000 | C21: -19600000 | D21: -21700000 | E21: -5000000
A22: Common Stock Issuance | F22: 5000000
A23: Net Issuance Payments Of Debt | B23: 74200000 | C23: -1600000 | D23: -99800000 | E23: 32900000
A24: Net Long Term Debt Issuance | B24: 74200000 | C24: -1600000 | D24: -99800000 | E24: 32900000
A25: Long Term Debt Payments | B25: -10800000 | C25: -42500000 | D25: -120000000 | E25: -19100000
A26: Long Term Debt Issuance | B26: 85000000 | C26: 40900000 | D26: 20000000 | E26: 52000000
A27: Investing Cash Flow | B27: -22700000 | C27: -78400000 | D27: -23200000 | E27: -24500000
A28: Cash Flow From Continuing Investing Activities | B28: -22700000 | C28: -78400000 | D28: -23200000 | E28: -24500000
A29: Net Other Investing Changes | E29: 100000 | F29: 100000
A30: Net Investment Purchase And Sale | B30: 0 | C30: -32100000 | D30: 0 | E30: 0
A31: Purchase Of Investment | B31: 0 | C31: -32100000 | D31: 0 | E31: 0
A32: Net Business Purchase And Sale | B32: -3200000 | C32: -25700000 | D32: 0 | E32: 0
A33: Sale Of Business | F33: 24700000
A34: Purchase Of Business | B34: -3200000 | C34: -25700000 | D34: 0 | E34: 0
A35: Net Intangibles Purchase And Sale | E35: 0 | F35: -100000
A36: Purchase Of Intangibles | E36: 0 | F36: -100000
A37: Net PPE Purchase And Sale | B37: -19500000 | C37: -20600000 | D37: -23200000 | E37: -24600000
A38: Sale Of PPE | B38: 2600000 | C38: 800000 | D38: 800000 | E38: 4700000
A39: Purchase Of PPE | B39: -22100000 | C39: -21400000 | D39: -24000000 | E39: -29300000
A40: Operating Cash Flow | B40: 65000000 | C40: 89700000 | D40: 188400000 | E40: -25100000
...

Sheet Cash flow (quarterly)
A1: Line item | B1: 2026-03-31 | C1: 2025-12-31 | D1: 2025-09-30 | E1: 2025-06-30 | F1: 2025-03-31 | G1: 2024-12-31
A2: Free Cash Flow | B2: -34500000 | C2: 9600000 | D2: 22200000 | E2: 18600000 | F2: -7500000
A3: Repurchase Of Capital Stock | B3: -60000000 | C3: -32200000 | D3: -22700000 | E3: -13400000 | F3: -20200000
A4: Repayment Of Debt | B4: -20000000 | C4: -10000000 | D4: 0 | E4: 0 | F4: -800000
A5: Issuance Of Debt | B5: 105000000 | C5: 45000000 | D5: 25000000 | E5: 0 | F5: 15000000
A6: Capital Expenditure | B6: -3300000 | C6: -4600000 | D6: -6500000 | E6: -3900000 | F6: -7100000
A7: Interest Paid Supplemental Data | B7: 4100000 | C7: 3300000 | D7: 3000000 | E7: 3100000 | F7: 2900000
A8: Income Tax Paid Supplemental Data | C8: 2200000 | D8: 2200000 | E8: 5500000 | F8: 3500000 | G8: 2300000
A9: End Cash Position | B9: 82600000 | C9: 106400000 | D9: 99400000 | E9: 80100000 | F9: 79500000
A10: Beginning Cash Position | B10: 106400000 | C10: 99400000 | D10: 80100000 | E10: 79500000 | F10: 99800000
A11: Effect Of Exchange Rate Changes | B11: 500000 | C11: -100000 | D11: 1500000 | E11: 900000 | F11: 700000
A12: Changes In Cash | B12: -24300000 | C12: 7100000 | D12: 17800000 | E12: -300000 | F12: -21000000
A13: Financing Cash Flow | B13: 17200000 | C13: -2700000 | D13: -3200000 | E13: -19100000 | F13: -13700000
A14: Cash Flow From Continuing Financing Activities | B14: 17200000 | C14: -2700000 | D14: -3200000 | E14: -19100000 | F14: -13700000
A15: Net Other Financing Charges | G15: 0
A16: Proceeds From Stock Option Exercised | B16: -2300000 | C16: 0 | D16: -100000 | E16: -300000 | F16: -2100000
A17: Cash Dividends Paid | B17: -5500000 | C17: -5500000 | D17: -5400000 | E17: -5400000 | F17: -5600000
A18: Common Stock Dividend Paid | B18: -5500000 | C18: -5500000 | D18: -5400000 | E18: -5400000 | F18: -5600000
A19: Net Common Stock Issuance | B19: -60000000 | C19: -32200000 | D19: -22700000 | E19: -13400000 | F19: -20200000
A20: Common Stock Payments | B20: -60000000 | C20: -32200000 | D20: -22700000 | E20: -13400000 | F20: -20200000
A21: Net Issuance Payments Of Debt | B21: 85000000 | C21: 35000000 | D21: 25000000 | E21: 0 | F21: 14200000
A22: Net Long Term Debt Issuance | B22: 85000000 | C22: 35000000 | D22: 25000000 | E22: 0 | F22: 14200000
A23: Long Term Debt Payments | B23: -20000000 | C23: -10000000 | D23: 0 | E23: 0 | F23: -800000
A24: Long Term Debt Issuance | B24: 105000000 | C24: 45000000 | D24: 25000000 | E24: 0 | F24: 15000000
A25: Investing Cash Flow | B25: -10300000 | C25: -4400000 | D25: -7700000 | E25: -3700000 | F25: -6900000
A26: Cash Flow From Continuing Investing Activities | B26: -10300000 | C26: -4400000 | D26: -7700000 | E26: -3700000 | F26: -6900000
A27: Net Investment Purchase And Sale | C27: 0 | D27: 0 | E27: 0 | F27: 0 | G27: 0
A28: Purchase Of Investment | C28: 0 | D28: 0 | E28: 0 | F28: 0 | G28: 0
A29: Net Business Purchase And Sale | B29: -7200000 | C29: 0 | D29: -3200000 | E29: 0 | F29: 0
A30: Purchase Of Business | B30: -7200000 | C30: 0 | D30: -3200000 | E30: 0 | F30: 0
A31: Net PPE Purchase And Sale | B31: -3100000 | C31: -4400000 | D31: -4500000 | E31: -3700000 | F31: -6900000
A32: Sale Of PPE | B32: 200000 | C32: 200000 | D32: 2000000 | E32: 200000 | F32: 200000
A33: Purchase Of PPE | B33: -3300000 | C33: -4600000 | D33: -6500000 | E33: -3900000 | F33: -7100000
A34: Operating Cash Flow | B34: -31200000 | C34: 14200000 | D34: 28700000 | E34: 22500000 | F34: -400000
A35: Cash Flow From Continuing Operating Activities | B35: -31200000 | C35: 14200000 | D35: 28700000 | E35: 22500000 | F35: -400000
A36: Change In Working Capital | B36: -51700000 | C36: 3900000 | D36: -15300000 | E36: -17000000 | F36: -32100000
A37: Change In Other Working Capital | B37: -12300000 | C37: -5500000 | D37: -3300000 | E37: -6100000 | F37: -26100000
A38: Change In Payables And Accrued Expense | B38: -2500000 | C38: 14200000 | D38: -9900000 | E38: 2500000 | F38: -8700000
A39: Change In Payable | B39: -2500000 | C39: 14200000 | D39: -9900000 | E39: 2500000 | F39: -8700000
A40: Change In Account Payable | B40: -2500000 | C40: 14200000 | D40: -9900000 | E40: 2500000 | F40: -8700000
...

Sheet Data flags
A1: Field | B1: Issue
A2: — | B2: no gaps detected
